Workbook
Name lender_paid_offset: #REF!

Sheet CONV
AJ1: PG 1 OF 12
B2: AmWest Corporate Office | T2: 45 DAYS | U2: -0.125
B3: 6 Pointe Dr. Suite 300
B4: Brea, CA 92821
B5: (714) 831-3333
B6: www.amwestwholesale.com
L7: Wholesale Rate sheet - Consumer Paid | O7: Effective: | R7: =TODAY() -> 46101
B9: FAST TRACK (FANNIE MAE & FREDDIE MAC)
B10: CONFORMING FIXED | Z10: HIGH BALANCE FIXED
B11: (FFT30) 30 YEAR | E11: (FMFT30) 30 YEAR | H11: (FFT20) 20 YEAR | K11: (FMFT20) 20 YEAR | N11: (FFT15) 15 YEAR | Q11: (FMFT15) 15 YEAR | T11: (FFT10) 10 YEAR | W11: (FMFT10) 10 YEAR | Z11: (FFT30HB) 30 YEAR | AC11: (FMFT30SC) 30 YEAR | AF11: ( FFT15HB) 15 YEAR | AI11: ( FMFT15SC) 15 YEAR
B12: RATE | C12: 30 Days | D12: 45 days | E12: RATE | F12: 30 Days | G12: 45 days | H12: RATE | I12: 30 Days | J12: 45 days | K12: RATE | L12: 30 Days | M12: 45 days | N12: RATE | O12: 30 Days | P12: 45 days | Q12: RATE | R12: 30 Days | S12: 45 days | T12: RATE | U12: 30 Days | V12: 45 days | W12: RATE | X12: 30 Days | Y12: 45 days | Z12: RATE | AA12: 30 Days | AB12: 45 days | AC12: RATE | AD12: 30 Days | AE12: 45 days | AF12: RATE | AG12: 30 Days | AH12: 45 days | AI12: RATE | AJ12: 30 Days | AK12: 45 days
B13: =LARGE('[1]Pricing '!$A$2506:$A$2531,1) -> 7.75 | C13: =100-VLOOKUP(B13,'[1]Pricing '!$A$2506:$K$2531,11,FALSE) -> -5.2391265 | D13: =C13-$U$2 -> -5.1141265 | E13: =LARGE('[1]Pricing '!$A$2677:$A$2702,1) -> 7.625 | F13: =100-VLOOKUP(E13,'[1]Pricing '!$A$2677:$K$2702,11,FALSE) -> -5.2757203 | G13: =F13-$U$2 -> -5.1507203 | H13: =LARGE('[1]Pricing '!$A$2648:$A$2673,1) -> 7.625 | I13: =100-VLOOKUP(H13,'[1]Pricing '!$A$2648:$K$2673,11,FALSE) -> -4.5407203 | J13: =I13-$U$2 -> -4.4157203 | K13: =LARGE('[1]Pricing '!$A$2733:$A$2758,1) -> 7.75 | L13: =100-VLOOKUP(K13,'[1]Pricing '!$A$2733:$K$2758,11,FALSE) -> -4.9841265 | M13: =L13-$U$2 -> -4.8591265 | N13: =LARGE('[1]Pricing '!$A$2534:$A$2558,1) -> 7.25 | O13: =100-VLOOKUP(N13,'[1]Pricing '!$A$2534:$K$2558,11,FALSE) -> -4.0152603 | P13: =O13-$U$2 -> -3.8902603 | Q13: =LARGE('[1]Pricing '!$A$2761:$A$2785,1) -> 7 | R13: =100-VLOOKUP(Q13,'[1]Pricing '!$A$2761:$K$2785,11,FALSE) -> -4.2350398 | S13: =R13-$U$2 -> -4.1100398 | T13: =LARGE('[1]Pricing '!$A$3052:$A$3077,1) -> 7.25 | U13: =100-VLOOKUP(T13,'[1]Pricing '!$A$3052:$K$3077,11,FALSE) -> -4.0712603 | V13: =U13-$U$2 -> -3.9462603 | W13: =LARGE('[1]Pricing '!$A$2788:$A$2812,1) -> 7.375 | X13: =100-VLOOKUP(W13,'[1]Pricing '!$A$2788:$K$2812,11,FALSE) -> -4.2670013 | Y13: =X13-$U$2 -> -4.1420013 | Z13: =LARGE('[1]Pricing '!$A$2561:$A$2586,1) -> 7.75 | AA13: =100-VLOOKUP(Z13,'[1]Pricing '!$A$2561:$K$2586,11,FALSE) -> -3.2067092 | AB13: =AA13-$U$2 -> -3.0817092 | AC13: =LARGE('[1]Pricing '!$A$2815:$A$2840,1) -> 7.75 | AD13: =100-VLOOKUP(AC13,'[1]Pricing '!$A$2815:$K$2840,11,FALSE) -> -3.2067092 | AE13: =AD13-$U$2 -> -3.0817092 | AF13: =LARGE('[1]Pricing '!$A$2589:$A$2614,1) -> 7.5 | AG13: =100-VLOOKUP(AF13,'[1]Pricing '!$A$2589:$K$2614,11,FALSE) -> -3.8437478 | AH13: =AG13-$U$2 -> -3.7187478 | AI13: =LARGE('[1]Pricing '!$A$2871:$A$2896,1) -> 7.25 | AJ13: =100-VLOOKUP(AI13,'[1]Pricing '!$A$2871:$K$2896,11,FALSE) -> -3.3422655 | AK13: =AJ13-$U$2 -> -3.2172655
B14: {=INDEX($A$162:$DE$162,0,MATCH(B13,$A$162:$DE$162,0)-1)} -> 7.625 | C14: =100-VLOOKUP(B14,'[1]Pricing '!$A$2506:$K$2531,11,FALSE) -> -5.2757203 | D14: =C14-$U$2 -> -5.1507203 | E14: {=INDEX($A$162:$DE$162,0,MATCH(E13,$A$162:$DE$162,0)-1)} -> 7.5 | F14: =100-VLOOKUP(E14,'[1]Pricing '!$A$2677:$K$2702,11,FALSE) -> -5.067206 | G14: =F14-$U$2 -> -4.942206 | H14: =H13-0.125 -> 7.5 | I14: =100-VLOOKUP(H14,'[1]Pricing '!$A$2648:$K$2673,11,FALSE) -> -4.149206 | J14: =I14-$U$2 -> -4.024206 | K14: =K13-0.125 -> 7.625 | L14: =100-VLOOKUP(K14,'[1]Pricing '!$A$2733:$K$2758,11,FALSE) -> -4.5407203 | M14: =L14-$U$2 -> -4.4157203 | N14: =N13-0.125 -> 7.125 | O14: =100-VLOOKUP(N14,'[1]Pricing '!$A$2534:$K$2558,11,FALSE) -> -3.7596219 | P14: =O14-$U$2 -> -3.6346219 | Q14: =Q13-0.125 -> 6.875 | R14: =100-VLOOKUP(Q14,'[1]Pricing '!$A$2761:$K$2785,11,FALSE) -> -4.0143409 | S14: =R14-$U$2 -> -3.8893409 | T14: =T13-0.125 -> 7.125 | U14: =100-VLOOKUP(T14,'[1]Pricing '!$A$3052:$K$3077,11,FALSE) -> -3.8466219 | V14: =U14-$U$2 -> -3.7216219 | W14: =W13-0.125 -> 7.25 | X14: =100-VLOOKUP(W14,'[1]Pricing '!$A$2788:$K$2812,11,FALSE) -> -4.0712603 | Y14: =X14-$U$2 -> -3.9462603 | Z14: =Z13-0.125 -> 7.625 | AA14: =100-VLOOKUP(Z14,'[1]Pricing '!$A$2561:$K$2586,11,FALSE) -> -3.6488846 | AB14: =AA14-$U$2 -> -3.5238846 | AC14: =AC13-0.125 -> 7.625 | AD14: =100-VLOOKUP(AC14,'[1]Pricing '!$A$2815:$K$2840,11,FALSE) -> -3.6488846 | AE14: =AD14-$U$2 -> -3.5238846 | AF14: =AF13-0.125 -> 7.375 | AG14: =100-VLOOKUP(AF14,'[1]Pricing '!$A$2589:$K$2614,11,FALSE) -> -3.6628836 | AH14: =AG14-$U$2 -> -3.5378836 | AI14: =AI13-0.125 -> 7.125 | AJ14: =100-VLOOKUP(AI14,'[1]Pricing '!$A$2871:$K$2896,11,FALSE) -> -3.6428149 | AK14: =AJ14-$U$2 -> -3.5178149
B15: {=INDEX($A$162:$DE$162,0,MATCH(B14,$A$162:$DE$162,0)-1)} -> 7.5 | C15: =100-VLOOKUP(B15,'[1]Pricing '!$A$2506:$K$2531,11,FALSE) -> -5.067206 | D15: =C15-$U$2 -> -4.942206 | E15: {=INDEX($A$162:$DE$162,0,MATCH(E14,$A$162:$DE$162,0)-1)} -> 7.375 | F15: =100-VLOOKUP(E15,'[1]Pricing '!$A$2677:$K$2702,11,FALSE) -> -4.7977794 | G15: =F15-$U$2 -> -4.6727794 | H15: =H14-0.125 -> 7.375 | I15: =100-VLOOKUP(H15,'[1]Pricing '!$A$2648:$K$2673,11,FALSE) -> -3.8957794 | J15: =I15-$U$2 -> -3.7707794 | K15: =K14-0.125 -> 7.5 | L15: =100-VLOOKUP(K15,'[1]Pricing '!$A$2733:$K$2758,11,FALSE) -> -4.149206 | M15: =L15-$U$2 -> -4.024206 | N15: =N14-0.125 -> 7 | O15: =100-VLOOKUP(N15,'[1]Pricing '!$A$2534:$K$2558,11,FALSE) -> -4.1100398 | P15: =O15-$U$2 -> -3.9850398 | Q15: =Q14-0.125 -> 6.75 | R15: =100-VLOOKUP(Q15,'[1]Pricing '!$A$2761:$K$2785,11,FALSE) -> -3.7662591 | S15: =R15-$U$2 -> -3.6412591 | T15: =T14-0.125 -> 7 | U15: =100-VLOOKUP(T15,'[1]Pricing '!$A$3052:$K$3077,11,FALSE) -> -4.1890398 | V15: =U15-$U$2 -> -4.0640398 | W15: =W14-0.125 -> 7.125 | X15: =100-VLOOKUP(W15,'[1]Pricing '!$A$2788:$K$2812,11,FALSE) -> -3.8466219 | Y15: =X15-$U$2 -> -3.7216219 | Z15: =Z14-0.125 -> 7.5 | AA15: =100-VLOOKUP(Z15,'[1]Pricing '!$A$2561:$K$2586,11,FALSE) -> -3.4762904 | AB15: =AA15-$U$2 -> -3.3512904 | AC15: =AC14-0.125 -> 7.5 | AD15: =100-VLOOKUP(AC15,'[1]Pricing '!$A$2815:$K$2840,11,FALSE) -> -3.4762904 | AE15: =AD15-$U$2 -> -3.3512904 | AF15: =AF14-0.125 -> 7.25 | AG15: =100-VLOOKUP(AF15,'[1]Pricing '!$A$2589:$K$2614,11,FALSE) -> -3.4672655 | AH15: =AG15-$U$2 -> -3.3422655 | AI15: =AI14-0.125 -> 7 | AJ15: =100-VLOOKUP(AI15,'[1]Pricing '!$A$2871:$K$2896,11,FALSE) -> -3.4413756 | AK15: =AJ15-$U$2 -> -3.3163756
B16: {=INDEX($A$162:$DE$162,0,MATCH(B15,$A$162:$DE$162,0)-1)} -> 7.375 | C16: =100-VLOOKUP(B16,'[1]Pricing '!$A$2506:$K$2531,11,FALSE) -> -4.7977794 | D16: =C16-$U$2 -> -4.6727794 | E16: {=INDEX($A$162:$DE$162,0,MATCH(E15,$A$162:$DE$162,0)-1)} -> 7.25 | F16: =100-VLOOKUP(E16,'[1]Pricing '!$A$2677:$K$2702,11,FALSE) -> -4.3192232 | G16: =F16-$U$2 -> -4.1942232 | H16: =H15-0.125 -> 7.25 | I16: =100-VLOOKUP(H16,'[1]Pricing '!$A$2648:$K$2673,11,FALSE) -> -3.6172232 | J16: =I16-$U$2 -> -3.4922232 | K16: =K15-0.125 -> 7.375 | L16: =100-VLOOKUP(K16,'[1]Pricing '!$A$2733:$K$2758,11,FALSE) -> -3.8957794 | M16: =L16-$U$2 -> -3.7707794 | N16: =N15-0.125 -> 6.875 | O16: =100-VLOOKUP(N16,'[1]Pricing '!$A$2534:$K$2558,11,FALSE) -> -3.8893409 | P16: =O16-$U$2 -> -3.7643409 | Q16: =Q15-0.125 -> 6.625 | R16: =100-VLOOKUP(Q16,'[1]Pricing '!$A$2761:$K$2785,11,FALSE) -> -3.5121048 | S16: =R16-$U$2 -> -3.3871048 | T16: =T15-0.125 -> 6.875 | U16: =100-VLOOKUP(T16,'[1]Pricing '!$A$3052:$K$3077,11,FALSE) -> -3.9713409 | V16: =U16-$U$2 -> -3.8463409 | W16: =W15-0.125 -> 7 | X16: =100-VLOOKUP(W16,'[1]Pricing '!$A$2788:$K$2812,11,FALSE) -> -4.1890398 | Y16: =X16-$U$2 -> -4.0640398 | Z16: =Z15-0.125 -> 7.375 | AA16: =100-VLOOKUP(Z16,'[1]Pricing '!$A$2561:$K$2586,11,FALSE) -> -3.1187664 | AB16: =AA16-$U$2 -> -2.9937664 | AC16: =AC15-0.125 -> 7.375 | AD16: =100-VLOOKUP(AC16,'[1]Pricing '!$A$2815:$K$2840,11,FALSE) -> -3.1187664 | AE16: =AD16-$U$2 -> -2.9937664 | AF16: =AF15-0.125 -> 7.125 | AG16: =100-VLOOKUP(AF16,'[1]Pricing '!$A$2589:$K$2614,11,FALSE) -> -3.7678149 | AH16: =AG16-$U$2 -> -3.6428149 | AI16: =AI15-0.125 -> 6.875 | AJ16: =100-VLOOKUP(AI16,'[1]Pricing '!$A$2871:$K$2896,11,FALSE) -> -2.8556408 | AK16: =AJ16-$U$2 -> -2.7306408
B17: {=INDEX($A$162:$DE$162,0,MATCH(B16,$A$162:$DE$162,0)-1)} -> 7.25 | C17: =100-VLOOKUP(B17,'[1]Pricing '!$A$2506:$K$2531,11,FALSE) -> -4.3192232 | D17: =C17-$U$2 -> -4.1942232 | E17: {=INDEX($A$162:$DE$162,0,MATCH(E16,$A$162:$DE$162,0)-1)} -> 7.125 | F17: =100-VLOOKUP(E17,'[1]Pricing '!$A$2677:$K$2702,11,FALSE) -> -4.1056343 | G17: =F17-$U$2 -> -3.9806343 | H17: =H16-0.125 -> 7.125 | I17: =100-VLOOKUP(H17,'[1]Pricing '!$A$2648:$K$2673,11,FALSE) -> -3.1156343 | J17: =I17-$U$2 -> -2.9906343 | K17: =K16-0.125 -> 7.25 | L17: =100-VLOOKUP(K17,'[1]Pricing '!$A$2733:$K$2758,11,FALSE) -> -3.6172232 | M17: =L17-$U$2 -> -3.4922232 | N17: =N16-0.125 -> 6.75 | O17: =100-VLOOKUP(N17,'[1]Pricing '!$A$2534:$K$2558,11,FALSE) -> -3.6412591 | P17: =O17-$U$2 -> -3.5162591 | Q17: =Q16-0.125 -> 6.5 | R17: =100-VLOOKUP(Q17,'[1]Pricing '!$A$2761:$K$2785,11,FALSE) -> -3.3369705 | S17: =R17-$U$2 -> -3.2119705 | T17: =T16-0.125 -> 6.75 | U17: =100-VLOOKUP(T17,'[1]Pricing '!$A$3052:$K$3077,11,FALSE) -> -3.7272591 | V17: =U17-$U$2 -> -3.6022591 | W17: =W16-0.125 -> 6.875 | X17: =100-VLOOKUP(W17,'[1]Pricing '!$A$2788:$K$2812,11,FALSE) -> -3.9713409 | Y17: =X17-$U$2 -> -3.8463409 | Z17: =Z16-0.125 -> 7.25 | AA17: =100-VLOOKUP(Z17,'[1]Pricing '!$A$2561:$K$2586,11,FALSE) -> -2.6460252 | AB17: =AA17-$U$2 -> -2.5210252 | AC17: =AC16-0.125 -> 7.25 | AD17: =100-VLOOKUP(AC17,'[1]Pricing '!$A$2815:$K$2840,11,FALSE) -> -2.6460252 | AE17: =AD17-$U$2 -> -2.5210252 | AF17: =AF16-0.125 -> 7 | AG17: =100-VLOOKUP(AF17,'[1]Pricing '!$A$2589:$K$2614,11,FALSE) -> -3.5663756 | AH17: =AG17-$U$2 -> -3.4413756 | AI17: =AI16-0.125 -> 6.75 | AJ17: =100-VLOOKUP(AI17,'[1]Pricing '!$A$2871:$K$2896,11,FALSE) -> -2.4802069 | AK17: =AJ17-$U$2 -> -2.3552069
B18: {=INDEX($A$162:$DE$162,0,MATCH(B17,$A$162:$DE$162,0)-1)} -> 7.125 | C18: =100-VLOOKUP(B18,'[1]Pricing '!$A$2506:$K$2531,11,FALSE) -> -4.1056343 | D18: =C18-$U$2 -> -3.9806343 | E18: {=INDEX($A$162:$DE$162,0,MATCH(E17,$A$162:$DE$162,0)-1)} -> 7 | F18: =100-VLOOKUP(E18,'[1]Pricing '!$A$2677:$K$2702,11,FALSE) -> -3.7784188 | G18: =F18-$U$2 -> -3.6534188 | H18: =H17-0.125 -> 7 | I18: =100-VLOOKUP(H18,'[1]Pricing '!$A$2648:$K$2673,11,FALSE) -> -2.7994188 | J18: =I18-$U$2 -> -2.6744188 | K18: =K17-0.125 -> 7.125 | L18: =100-VLOOKUP(K18,'[1]Pricing '!$A$2733:$K$2758,11,FALSE) -> -3.1156343 | M18: =L18-$U$2 -> -2.9906343 | N18: =N17-0.125 -> 6.625 | O18: =100-VLOOKUP(N18,'[1]Pricing '!$A$2534:$K$2558,11,FALSE) -> -3.3871048 | P18: =O18-$U$2 -> -3.2621048 | Q18: =Q17-0.125 -> 6.375 | R18: =100-VLOOKUP(Q18,'[1]Pricing '!$A$2761:$K$2785,11,FALSE) -> -3.0965438 | S18: =R18-$U$2 -> -2.9715438 | T18: =T17-0.125 -> 6.625 | U18: =100-VLOOKUP(T18,'[1]Pricing '!$A$3052:$K$3077,11,FALSE) -> -3.5101048 | V18: =U18-$U$2 -> -3.3851048 | W18: =W17-0.125 -> 6.75 | X18: =100-VLOOKUP(W18,'[1]Pricing '!$A$2788:$K$2812,11,FALSE) -> -3.7272591 | Y18: =X18-$U$2 -> -3.6022591 | Z18: =Z17-0.125 -> 7.125 | AA18: =100-VLOOKUP(Z18,'[1]Pricing '!$A$2561:$K$2586,11,FALSE) -> -2.890445 | AB18: =AA18-$U$2 -> -2.765445 | AC18: =AC17-0.125 -> 7.125 | AD18: =100-VLOOKUP(AC18,'[1]Pricing '!$A$2815:$K$2840,11,FALSE) -> -2.890445 | AE18: =AD18-$U$2 -> -2.765445 | AF18: =AF17-0.125 -> 6.875 | AG18: =100-VLOOKUP(AF18,'[1]Pricing '!$A$2589:$K$2614,11,FALSE) -> -2.9806408 | AH18: =AG18-$U$2 -> -2.8556408 | AI18: =AI17-0.125 -> 6.625 | AJ18: =100-VLOOKUP(AI18,'[1]Pricing '!$A$2871:$K$2896,11,FALSE) -> -2.3511124 | AK18: =AJ18-$U$2 -> -2.2261124
B19: {=INDEX($A$162:$DE$162,0,MATCH(B18,$A$162:$DE$162,0)-1)} -> 7 | C19: =100-VLOOKUP(B19,'[1]Pricing '!$A$2506:$K$2531,11,FALSE) -> -3.7784188 | D19: =C19-$U$2 -> -3.6534188 | E19: {=INDEX($A$162:$DE$162,0,MATCH(E18,$A$162:$DE$162,0)-1)} -> 6.875 | F19: =100-VLOOKUP(E19,'[1]Pricing '!$A$2677:$K$2702,11,FALSE) -> -3.3166371 | G19: =F19-$U$2 -> -3.1916371 | H19: =H18-0.125 -> 6.875 | I19: =100-VLOOKUP(H19,'[1]Pricing '!$A$2648:$K$2673,11,FALSE) -> -2.5436371 | J19: =I19-$U$2 -> -2.4186371 | K19: =K18-0.125 -> 7 | L19: =100-VLOOKUP(K19,'[1]Pricing '!$A$2733:$K$2758,11,FALSE) -> -2.7994188 | M19: =L19-$U$2 -> -2.6744188 | N19: =N18-0.125 -> 6.5 | O19: =100-VLOOKUP(N19,'[1]Pricing '!$A$2534:$K$2558,11,FALSE) -> -3.2119705 | P19: =O19-$U$2 -> -3.0869705 | Q19: =Q18-0.125 -> 6.25 | R19: =100-VLOOKUP(Q19,'[1]Pricing '!$A$2761:$K$2785,11,FALSE) -> -2.8050742 | S19: =R19-$U$2 -> -2.6800742 | T19: =T18-0.125 -> 6.5 | U19: =100-VLOOKUP(T19,'[1]Pricing '!$A$3052:$K$3077,11,FALSE) -> -3.2889705 | V19: =U19-$U$2 -> -3.1639705 | W19: =W18-0.125 -> 6.625 | X19: =100-VLOOKUP(W19,'[1]Pricing '!$A$2788:$K$2812,11,FALSE) -> -3.5101048 | Y19: =X19-$U$2 -> -3.3851048 | Z19: =Z18-0.125 -> 7 | AA19: =100-VLOOKUP(Z19,'[1]Pricing '!$A$2561:$K$2586,11,FALSE) -> -2.5778289 | AB19: =AA19-$U$2 -> -2.4528289 | AC19: =AC18-0.125 -> 7 | AD19: =100-VLOOKUP(AC19,'[1]Pricing '!$A$2815:$K$2840,11,FALSE) -> -2.5778289 | AE19: =AD19-$U$2 -> -2.4528289 | AF19: =AF18-0.125 -> 6.75 | AG19: =100-VLOOKUP(AF19,'[1]Pricing '!$A$2589:$K$2614,11,FALSE) -> -2.6052069 | AH19: =AG19-$U$2 -> -2.4802069 | AI19: =AI18-0.125 -> 6.5 | AJ19: =100-VLOOKUP(AI19,'[1]Pricing '!$A$2871:$K$2896,11,FALSE) -> -2.1321443 | AK19: =AJ19-$U$2 -> -2.0071443
B20: {=INDEX($A$162:$DE$162,0,MATCH(B19,$A$162:$DE$162,0)-1)} -> 6.875 | C20: =100-VLOOKUP(B20,'[1]Pricing '!$A$2506:$K$2531,11,FALSE) -> -3.3166371 | D20: =C20-$U$2 -> -3.1916371 | E20: {=INDEX($A$162:$DE$162,0,MATCH(E19,$A$162:$DE$162,0)-1)} -> 6.75 | F20: =100-VLOOKUP(E20,'[1]Pricing '!$A$2677:$K$2702,11,FALSE) -> -2.7760354 | G20: =F20-$U$2 -> -2.6510354 | H20: =H19-0.125 -> 6.75 | I20: =100-VLOOKUP(H20,'[1]Pricing '!$A$2648:$K$2673,11,FALSE) -> -2.2440354 | J20: =I20-$U$2 -> -2.1190354 | K20: =K19-0.125 -> 6.875 | L20: =100-VLOOKUP(K20,'[1]Pricing '!$A$2733:$K$2758,11,FALSE) -> -2.5436371 | M20: =L20-$U$2 -> -2.4186371 | N20: =N19-0.125 -> 6.375 | O20: =100-VLOOKUP(N20,'[1]Pricing '!$A$2534:$K$2558,11,FALSE) -> -2.9715438 | P20: =O20-$U$2 -> -2.8465438 | Q20: =Q19-0.125 -> 6.125 | R20: =100-VLOOKUP(Q20,'[1]Pricing '!$A$2761:$K$2785,11,FALSE) -> -2.4699316 | S20: =R20-$U$2 -> -2.3449316 | T20: =T19-0.125 -> 6.375 | U20: =100-VLOOKUP(T20,'[1]Pricing '!$A$3052:$K$3077,11,FALSE) -> -3.0515438 | V20: =U20-$U$2 -> -2.9265438 | W20: =W19-0.125 -> 6.5 | X20: =100-VLOOKUP(W20,'[1]Pricing '!$A$2788:$K$2812,11,FALSE) -> -3.2889705 | Y20: =X20-$U$2 -> -3.1639705 | Z20: =Z19-0.125 -> 6.875 | AA20: =100-VLOOKUP(Z20,'[1]Pricing '!$A$2561:$K$2586,11,FALSE) -> -2.3787035 | AB20: =AA20-$U$2 -> -2.2537035 | AC20: =AC19-0.125 -> 6.875 | AD20: =100-VLOOKUP(AC20,'[1]Pricing '!$A$2815:$K$2840,11,FALSE) -> -2.3787035 | AE20: =AD20-$U$2 -> -2.2537035 | AF20: =AF19-0.125 -> 6.625 | AG20: =100-VLOOKUP(AF20,'[1]Pricing '!$A$2589:$K$2614,11,FALSE) -> -2.4761124 | AH20: =AG20-$U$2 -> -2.3511124 | AI20: =AI19-0.125 -> 6.375 | AJ20: =100-VLOOKUP(AI20,'[1]Pricing '!$A$2871:$K$2896,11,FALSE) -> -1.8776478 | AK20: =AJ20-$U$2 -> -1.7526478
B21: {=INDEX($A$162:$DE$162,0,MATCH(B20,$A$162:$DE$162,0)-1)} -> 6.75 | C21: =100-VLOOKUP(B21,'[1]Pricing '!$A$2506:$K$2531,11,FALSE) -> -2.7760354 | D21: =C21-$U$2 -> -2.6510354 | E21: {=INDEX($A$162:$DE$162,0,MATCH(E20,$A$162:$DE$162,0)-1)} -> 6.625 | F21: =100-VLOOKUP(E21,'[1]Pricing '!$A$2677:$K$2702,11,FALSE) -> -2.6001419 | G21: =F21-$U$2 -> -2.4751419 | H21: =H20-0.125 -> 6.625 | I21: =100-VLOOKUP(H21,'[1]Pricing '!$A$2648:$K$2673,11,FALSE) -> -2.1781419 | J21: =I21-$U$2 -> -2.0531419 | K21: =K20-0.125 -> 6.75 | L21: =100-VLOOKUP(K21,'[1]Pricing '!$A$2733:$K$2758,11,FALSE) -> -2.2440354 | M21: =L21-$U$2 -> -2.1190354 | N21: =N20-0.125 -> 6.25 | O21: =100-VLOOKUP(N21,'[1]Pricing '!$A$2534:$K$2558,11,FALSE) -> -2.6800742 | P21: =O21-$U$2 -> -2.5550742 | Q21: =Q20-0.125 -> 6 | R21: =100-VLOOKUP(Q21,'[1]Pricing '!$A$2761:$K$2785,11,FALSE) -> -2.2045454 | S21: =R21-$U$2 -> -2.0795454 | T21: =T20-0.125 -> 6.25 | U21: =100-VLOOKUP(T21,'[1]Pricing '!$A$3052:$K$3077,11,FALSE) -> -2.7630742 | V21: =U21-$U$2 -> -2.6380742 | W21: =W20-0.125 -> 6.375 | X21: =100-VLOOKUP(W21,'[1]Pricing '!$A$2788:$K$2812,11,FALSE) -> -3.0515438 | Y21: =X21-$U$2 -> -2.9265438 | Z21: =Z20-0.125 -> 6.75 | AA21: =100-VLOOKUP(Z21,'[1]Pricing '!$A$2561:$K$2586,11,FALSE) -> -1.8256148 | AB21: =AA21-$U$2 -> -1.7006148 | AC21: =AC20-0.125 -> 6.75 | AD21: =100-VLOOKUP(AC21,'[1]Pricing '!$A$2815:$K$2840,11,FALSE) -> -1.8256148 | AE21: =AD21-$U$2 -> -1.7006148 | AF21: =AF20-0.125 -> 6.5 | AG21: =100-VLOOKUP(AF21,'[1]Pricing '!$A$2589:$K$2614,11,FALSE) -> -2.2571443 | AH21: =AG21-$U$2 -> -2.1321443 | AI21: =AI20-0.125 -> 6.25 | AJ21: =100-VLOOKUP(AI21,'[1]Pricing '!$A$2871:$K$2896,11,FALSE) -> -1.5080034 | AK21: =AJ21-$U$2 -> -1.3830034
B22: {=INDEX($A$162:$DE$162,0,MATCH(B21,$A$162:$DE$162,0)-1)} -> 6.625 | C22: =100-VLOOKUP(B22,'[1]Pricing '!$A$2506:$K$2531,11,FALSE) -> -2.6001419 | D22: =C22-$U$2 -> -2.4751419 | E22: {=INDEX($A$162:$DE$162,0,MATCH(E21,$A$162:$DE$162,0)-1)} -> 6.5 | F22: =100-VLOOKUP(E22,'[1]Pricing '!$A$2677:$K$2702,11,FALSE) -> -2.228558 | G22: =F22-$U$2 -> -2.103558 | H22: =H21-0.125 -> 6.5 | I22: =100-VLOOKUP(H22,'[1]Pricing '!$A$2648:$K$2673,11,FALSE) -> -1.854558 | J22: =I22-$U$2 -> -1.729558 | K22: =K21-0.125 -> 6.625 | L22: =100-VLOOKUP(K22,'[1]Pricing '!$A$2733:$K$2758,11,FALSE) -> -2.1781419 | M22: =L22-$U$2 -> -2.0531419 | N22: =N21-0.125 -> 6.125 | O22: =100-VLOOKUP(N22,'[1]Pricing '!$A$2534:$K$2558,11,FALSE) -> -2.3449316 | P22: =O22-$U$2 -> -2.2199316 | Q22: =Q21-0.125 -> 5.875 | R22: =100-VLOOKUP(Q22,'[1]Pricing '!$A$2761:$K$2785,11,FALSE) -> -1.9324186 | S22: =R22-$U$2 -> -1.8074186 | T22: =T21-0.125 -> 6.125 | U22: =100-VLOOKUP(T22,'[1]Pricing '!$A$3052:$K$3077,11,FALSE) -> -2.4469316 | V22: =U22-$U$2 -> -2.3219316 | W22: =W21-0.125 -> 6.25 | X22: =100-VLOOKUP(W22,'[1]Pricing '!$A$2788:$K$2812,11,FALSE) -> -2.7630742 | Y22: =X22-$U$2 -> -2.6380742 | Z22: =Z21-0.125 -> 6.625 | AA22: =100-VLOOKUP(Z22,'[1]Pricing '!$A$2561:$K$2586,11,FALSE) -> -1.8382554 | AB22: =AA22-$U$2 -> -1.7132554 | AC22: =AC21-0.125 -> 6.625 | AD22: =100-VLOOKUP(AC22,'[1]Pricing '!$A$2815:$K$2840,11,FALSE) -> -1.8382554 | AE22: =AD22-$U$2 -> -1.7132554 | AF22: =AF21-0.125 -> 6.375 | AG22: =100-VLOOKUP(AF22,'[1]Pricing '!$A$2589:$K$2614,11,FALSE) -> -2.0026478 | AH22: =AG22-$U$2 -> -1.8776478 | AI22: =AI21-0.125 -> 6.125 | AJ22: =100-VLOOKUP(AI22,'[1]Pricing '!$A$2871:$K$2896,11,FALSE) -> -1.2463059 | AK22: =AJ22-$U$2 -> -1.1213059
B23: {=INDEX($A$162:$DE$162,0,MATCH(B22,$A$162:$DE$162,0)-1)} -> 6.5 | C23: =100-VLOOKUP(B23,'[1]Pricing '!$A$2506:$K$2531,11,FALSE) -> -2.228558 | D23: =C23-$U$2 -> -2.103558 | E23: {=INDEX($A$162:$DE$162,0,MATCH(E22,$A$162:$DE$162,0)-1)} -> 6.375 | F23: =100-VLOOKUP(E23,'[1]Pricing '!$A$2677:$K$2702,11,FALSE) -> -1.8965731 | G23: =F23-$U$2 -> -1.7715731 | H23: =H22-0.125 -> 6.375 | I23: =100-VLOOKUP(H23,'[1]Pricing '!$A$2648:$K$2673,11,FALSE) -> -1.4895731 | J23: =I23-$U$2 -> -1.3645731 | K23: =K22-0.125 -> 6.5 | L23: =100-VLOOKUP(K23,'[1]Pricing '!$A$2733:$K$2758,11,FALSE) -> -1.854558 | M23: =L23-$U$2 -> -1.729558 | N23: =N22-0.125 -> 6 | O23: =100-VLOOKUP(N23,'[1]Pricing '!$A$2534:$K$2558,11,FALSE) -> -2.0795454 | P23: =O23-$U$2 -> -1.9545454 | Q23: =Q22-0.125 -> 5.75 | R23: =100-VLOOKUP(Q23,'[1]Pricing '!$A$2761:$K$2785,11,FALSE) -> -1.5290574 | S23: =R23-$U$2 -> -1.4040574 | T23: =T22-0.125 -> 6 | U23: =100-VLOOKUP(T23,'[1]Pricing '!$A$3052:$K$3077,11,FALSE) -> -2.1825454 | V23: =U23-$U$2 -> -2.0575454 | W23: =W22-0.125 -> 6.125 | X23: =100-VLOOKUP(W23,'[1]Pricing '!$A$2788:$K$2812,11,FALSE) -> -2.4469316 | Y23: =X23-$U$2 -> -2.3219316 | Z23: =Z22-0.125 -> 6.5 | AA23: =100-VLOOKUP(Z23,'[1]Pricing '!$A$2561:$K$2586,11,FALSE) -> -1.5711154 | AB23: =AA23-$U$2 -> -1.4461154 | AC23: =AC22-0.125 -> 6.5 | AD23: =100-VLOOKUP(AC23,'[1]Pricing '!$A$2815:$K$2840,11,FALSE) -> -1.5711154 | AE23: =AD23-$U$2 -> -1.4461154 | AF23: =AF22-0.125 -> 6.25 | AG23: =100-VLOOKUP(AF23,'[1]Pricing '!$A$2589:$K$2614,11,FALSE) -> -1.6330034 | AH23: =AG23-$U$2 -> -1.5080034 | AI23: =AI22-0.125 -> 6 | AJ23: =100-VLOOKUP(AI23,'[1]Pricing '!$A$2871:$K$2896,11,FALSE) -> -0.92586102 | AK23: =AJ23-$U$2 -> -0.80086102
B24: {=INDEX($A$162:$DE$162,0,MATCH(B23,$A$162:$DE$162,0)-1)} -> 6.375 | C24: =100-VLOOKUP(B24,'[1]Pricing '!$A$2506:$K$2531,11,FALSE) -> -1.8965731 | D24: =C24-$U$2 -> -1.7715731 | E24: {=INDEX($A$162:$DE$162,0,MATCH(E23,$A$162:$DE$162,0)-1)} -> 6.25 | F24: =100-VLOOKUP(E24,'[1]Pricing '!$A$2677:$K$2702,11,FALSE) -> -1.4479342 | G24: =F24-$U$2 -> -1.3229342 | H24: =H23-0.125 -> 6.25 | I24: =100-VLOOKUP(H24,'[1]Pricing '!$A$2648:$K$2673,11,FALSE) -> -1.0939342 | J24: =I24-$U$2 -> -0.96893415 | K24: =K23-0.125 -> 6.375 | L24: =100-VLOOKUP(K24,'[1]Pricing '!$A$2733:$K$2758,11,FALSE) -> -1.4895731 | M24: =L24-$U$2 -> -1.3645731 | N24: =N23-0.125 -> 5.875 | O24: =100-VLOOKUP(N24,'[1]Pricing '!$A$2534:$K$2558,11,FALSE) -> -1.8074186 | P24: =O24-$U$2 -> -1.6824186 | Q24: =Q23-0.125 -> 5.625 | R24: =100-VLOOKUP(Q24,'[1]Pricing '!$A$2761:$K$2785,11,FALSE) -> -1.1915764 | S24: =R24-$U$2 -> -1.0665764 | T24: =T23-0.125 -> 5.875 | U24: =100-VLOOKUP(T24,'[1]Pricing '!$A$3052:$K$3077,11,FALSE) -> -1.9144186 | V24: =U24-$U$2 -> -1.7894186 | W24: =W23-0.125 -> 6 | X24: =100-VLOOKUP(W24,'[1]Pricing '!$A$2788:$K$2812,11,FALSE) -> -2.1825454 | Y24: =X24-$U$2 -> -2.0575454 | Z24: =Z23-0.125 -> 6.375 | AA24: =100-VLOOKUP(Z24,'[1]Pricing '!$A$2561:$K$2586,11,FALSE) -> -1.3176457 | AB24: =AA24-$U$2 -> -1.1926457 | AC24: =AC23-0.125 -> 6.375 | AD24: =100-VLOOKUP(AC24,'[1]Pricing '!$A$2815:$K$2840,11,FALSE) -> -1.3176457 | AE24: =AD24-$U$2 -> -1.1926457 | AF24: =AF23-0.125 -> 6.125 | AG24: =100-VLOOKUP(AF24,'[1]Pricing '!$A$2589:$K$2614,11,FALSE) -> -1.3713059 | AH24: =AG24-$U$2 -> -1.2463059 | AI24: =AI23-0.125 -> 5.875 | AJ24: =100-VLOOKUP(AI24,'[1]Pricing '!$A$2871:$K$2896,11,FALSE) -> -0.63290801 | AK24: =AJ24-$U$2 -> -0.50790801
B25: {=INDEX($A$162:$DE$162,0,MATCH(B24,$A$162:$DE$162,0)-1)} -> 6.25 | C25: =100-VLOOKUP(B25,'[1]Pricing '!$A$2506:$K$2531,11,FALSE) -> -1.4479342 | D25: =C25-$U$2 -> -1.3229342 | E25: {=INDEX($A$162:$DE$162,0,MATCH(E24,$A$162:$DE$162,0)-1)} -> 6.125 | F25: =100-VLOOKUP(E25,'[1]Pricing '!$A$2677:$K$2702,11,FALSE) -> -1.0084619 | G25: =F25-$U$2 -> -0.88346194 | H25: =H24-0.125 -> 6.125 | I25: =100-VLOOKUP(H25,'[1]Pricing '!$A$2648:$K$2673,11,FALSE) -> -0.94046194 | J25: =I25-$U$2 -> -0.81546194 | K25: =K24-0.125 -> 6.25 | L25: =100-VLOOKUP(K25,'[1]Pricing '!$A$2733:$K$2758,11,FALSE) -> -1.0939342 | M25: =L25-$U$2 -> -0.96893415 | N25: =N24-0.125 -> 5.75 | O25: =100-VLOOKUP(N25,'[1]Pricing '!$A$2534:$K$2558,11,FALSE) -> -1.4040574 | P25: =O25-$U$2 -> -1.2790574 | Q25: =Q24-0.125 -> 5.5 | R25: =100-VLOOKUP(Q25,'[1]Pricing '!$A$2761:$K$2785,11,FALSE) -> -0.86875712 | S25: =R25-$U$2 -> -0.74375712 | T25: =T24-0.125 -> 5.75 | U25: =100-VLOOKUP(T25,'[1]Pricing '!$A$3052:$K$3077,11,FALSE) -> -1.5130574 | V25: =U25-$U$2 -> -1.3880574 | W25: =W24-0.125 -> 5.875 | X25: =100-VLOOKUP(W25,'[1]Pricing '!$A$2788:$K$2812,11,FALSE) -> -1.9144186 | Y25: =X25-$U$2 -> -1.7894186 | Z25: =Z24-0.125 -> 6.25 | AA25: =100-VLOOKUP(Z25,'[1]Pricing '!$A$2561:$K$2586,11,FALSE) -> -0.9273983 | AB25: =AA25-$U$2 -> -0.8023983 | AC25: =AC24-0.125 -> 6.25 | AD25: =100-VLOOKUP(AC25,'[1]Pricing '!$A$2815:$K$2840,11,FALSE) -> -0.9273983 | AE25: =AD25-$U$2 -> -0.8023983 | AF25: =AF24-0.125 -> 6 | AG25: =100-VLOOKUP(AF25,'[1]Pricing '!$A$2589:$K$2614,11,FALSE) -> -1.050861 | AH25: =AG25-$U$2 -> -0.92586102 | AI25: =AI24-0.125 -> 5.75 | AJ25: =100-VLOOKUP(AI25,'[1]Pricing '!$A$2871:$K$2896,11,FALSE) -> -0.15871406 | AK25: =AJ25-$U$2 -> -0.033714064
... B37: {=INDEX($A$162:$DE$162,0,MATCH(B36,$A$162:$DE$162,0)-1)} -> 4.875 | C37: =100-VLOOKUP(B37,'[1]Pricing '!$A$2506:$K$2531,11,FALSE) -> 4.6669012 | D37: =C37-$U$2 -> 4.7919012 | E37: {=INDEX($A$162:$DE$162,0,MATCH(E36,$A$162:$DE$162,0)-1)} -> 4.75 | F37: =100-VLOOKUP(E37,'[1]Pricing '!$A$2677:$K$2702,11,FALSE) -> 5.5315774 | G37: =F37-$U$2 -> 5.6565774 | H37: =H36-0.125 -> 4.625 | I37: =100-VLOOKUP(H37,'[1]Pricing '!$A$2648:$K$2673,11,FALSE) -> 5.2745101 | J37: =I37-$U$2 -> 5.3995101 | K37: =K36-0.125 -> 4.75 | L37: =100-VLOOKUP(K37,'[1]Pricing '!$A$2733:$K$2758,11,FALSE) -> 4.4765774 | M37: =L37-$U$2 -> 4.6015774 | N37: =N36-0.125 -> 4.25 | O37: =100-VLOOKUP(N37,'[1]Pricing '!$A$2534:$K$2558,11,FALSE) -> 3.1147495 | P37: =O37-$U$2 -> 3.2397495 | Q37: =Q36-0.125 -> 4 | R37: =100-VLOOKUP(Q37,'[1]Pricing '!$A$2761:$K$2785,11,FALSE) -> 2.5834823 | S37: =R37-$U$2 -> 2.7084823 | T37: =T36-0.125 -> 4.25 | U37: =100-VLOOKUP(T37,'[1]Pricing '!$A$3052:$K$3077,11,FALSE) -> 2.8177495 | V37: =U37-$U$2 -> 2.9427495 | W37: =W36-0.125 -> 4.375 | X37: =100-VLOOKUP(W37,'[1]Pricing '!$A$2788:$K$2812,11,FALSE) -> 2.2743055 | Y37: =X37-$U$2 -> 2.3993055 | Z37: =Z36-0.125 -> 4.75 | AA37: =100-VLOOKUP(Z37,'[1]Pricing '!$A$2561:$K$2586,11,FALSE) -> 6.5086638 | AB37: =AA37-$U$2 -> 6.6336638 | AC37: =AC36-0.125 -> 4.75 | AD37: =100-VLOOKUP(AC37,'[1]Pricing '!$A$2815:$K$2840,11,FALSE) -> 6.5086638 | AE37: =AD37-$U$2 -> 6.6336638 | AF37: =AF36-0.125 -> 4.5 | AG37: =100-VLOOKUP(AF37,'[1]Pricing '!$A$2589:$K$2614,11,FALSE) -> 3.7635388 | AH37: =AG37-$U$2 -> 3.8885388 | AI37: =AI36-0.125 -> 4.25 | AJ37: =100-VLOOKUP(AI37,'[1]Pricing '!$A$2871:$K$2896,11,FALSE) -> 4.8893076 | AK37: =AJ37-$U$2 -> 5.0143076
B39: FIXED PROGRAMS (FANNIE MAE & FREDDIE MAC)
B40: CONFORMING FIXED | Z40: HIGH BALANCE FIXED
B41: (FCF30) 30 YEAR | E41: (FM30) / (FM30 RP) 30 YEAR | H41: (FCF20) 20 YEAR | K41: (FM20) 20 YEAR | N41: (FCF15) 15 YEAR | Q41: (FM15) / (FM15 RP) 15 YEAR | T41: (FCF10) 10 YEAR | W41: (FM10) 10 YEAR | Z41: (FCF30HB) 30 YEAR | AC41: (FMSC30) 30 YEAR | AF41: ( FCF15HB) 15 YEAR | AI41: (FMSC15) 15 YEAR
B42: RATE | C42: 30 Days | D42: 45 days | E42: RATE | F42: 30 Days | G42: 45 days | H42: RATE | I42: 30 Days | J42: 45 days | K42: RATE | L42: 30 Days | M42: 45 days | N42: RATE | O42: 30 Days | P42: 45 days | Q42: RATE | R42: 30 Days | S42: 45 days | T42: RATE | U42: 30 Days | V42: 45 days | W42: RATE | X42: 30 Days | Y42: 45 days | Z42: RATE | AA42: 30 Days | AB42: 45 days | AC42: RATE | AD42: 30 Days | AE42: 45 days | AF42: RATE | AG42: 30 Days | AH42: 45 days | AI42: RATE | AJ42: 30 Days | AK42: 45 days
B43: =LARGE('[1]Pricing '!$A$6:$A$30,1) -> 7.625 | C43: =100-VLOOKUP(B43,'[1]Pricing '!$A$6:$K$30,11,FALSE) -> -4.2757203 | D43: =C43-$U$2 -> -4.1507203 | E43: =LARGE('[1]Pricing '!$A$566:$A$590,1) -> 7.875 | F43: =100-VLOOKUP(E43,'[1]Pricing '!$A$566:$K$590,11,FALSE) -> -4.500331 | G43: =F43-$U$2 -> -4.375331 | H43: =LARGE('[1]Pricing '!$A$59:$A$83,1) -> 7.5 | I43: =100-VLOOKUP(H43,'[1]Pricing '!$A$59:$K$83,11,FALSE) -> -3.274206 | J43: =I43-$U$2 -> -3.149206 | K43: =LARGE('[1]Pricing '!$A$593:$A$617,1) -> 7.5 | L43: =100-VLOOKUP(K43,'[1]Pricing '!$A$593:$K$617,11,FALSE) -> -3.274206 | M43: =L43-$U$2 -> -3.149206 | N43: =LARGE('[1]Pricing '!$A$86:$A$110,1) -> 7 | O43: =100-VLOOKUP(N43,'[1]Pricing '!$A$86:$K$110,11,FALSE) -> -3.2350398 | P43: =O43-$U$2 -> -3.1100398 | Q43: =LARGE('[1]Pricing '!$A$620:$A$644,1) -> 7 | R43: =100-VLOOKUP(Q43,'[1]Pricing '!$A$620:$K$644,11,FALSE) -> -3.2350398 | S43: =R43-$U$2 -> -3.1100398 | T43: =LARGE('[1]Pricing '!$A$113:$A$137,1) -> 7.125 | U43: =100-VLOOKUP(T43,'[1]Pricing '!$A$113:$K$137,11,FALSE) -> -2.8466219 | V43: =U43-$U$2 -> -2.7216219 | W43: =LARGE('[1]Pricing '!$A$647:$A$671,1) -> 7.375 | X43: =100-VLOOKUP(W43,'[1]Pricing '!$A$647:$K$671,11,FALSE) -> -3.2670013 | Y43: =X43-$U$2 -> -3.1420013 | Z43: =LARGE('[1]Pricing '!$A$167:$A$191,1) -> 7.75 | AA43: =100-VLOOKUP(Z43,'[1]Pricing '!$A$167:$K$191,11,FALSE) -> -2.3317092 | AB43: =AA43-$U$2 -> -2.2067092 | AC43: =LARGE('[1]Pricing '!$A$674:$A$698,1) -> 7.875 | AD43: =100-VLOOKUP(AC43,'[1]Pricing '!$A$674:$K$698,11,FALSE) -> -2.7171899 | AE43: =AD43-$U$2 -> -2.5921899 | AF43: =LARGE('[1]Pricing '!$A$194:$A$218,1) -> 7.5 | AG43: =100-VLOOKUP(AF43,'[1]Pricing '!$A$194:$K$218,11,FALSE) -> -2.9687478 | AH43: =AG43-$U$2 -> -2.8437478 | AI43: =LARGE('[1]Pricing '!$A$701:$A$725,1) -> 7.5 | AJ43: =100-VLOOKUP(AI43,'[1]Pricing '!$A$701:$K$725,11,FALSE) -> -2.9687478 | AK43: =AJ43-$U$2 -> -2.8437478
B44: {=INDEX($A$162:$DE$162,0,MATCH(B43,$A$162:$DE$162,0)-1)} -> 7.5 | C44: =100-VLOOKUP(B44,'[1]Pricing '!$A$6:$K$30,11,FALSE) -> -4.067206 | D44: =C44-$U$2 -> -3.942206 | E44: {=INDEX($A$162:$DE$162,0,MATCH(E43,$A$162:$DE$162,0)-1)} -> 7.75 | F44: =100-VLOOKUP(E44,'[1]Pricing '!$A$566:$K$590,11,FALSE) -> -4.2391265 | G44: =F44-$U$2 -> -4.1141265 | H44: =H43-0.125 -> 7.375 | I44: =100-VLOOKUP(H44,'[1]Pricing '!$A$59:$K$83,11,FALSE) -> -3.0207794 | J44: =I44-$U$2 -> -2.8957794 | K44: =K43-0.125 -> 7.375 | L44: =100-VLOOKUP(K44,'[1]Pricing '!$A$593:$K$617,11,FALSE) -> -3.0207794 | M44: =L44-$U$2 -> -2.8957794 | N44: =N43-0.125 -> 6.875 | O44: =100-VLOOKUP(N44,'[1]Pricing '!$A$86:$K$110,11,FALSE) -> -3.0143409 | P44: =O44-$U$2 -> -2.8893409 | Q44: =Q43-0.125 -> 6.875 | R44: =100-VLOOKUP(Q44,'[1]Pricing '!$A$620:$K$644,11,FALSE) -> -3.0143409 | S44: =R44-$U$2 -> -2.8893409 | T44: =T43-0.125 -> 7 | U44: =100-VLOOKUP(T44,'[1]Pricing '!$A$113:$K$137,11,FALSE) -> -3.1890398 | V44: =U44-$U$2 -> -3.0640398 | W44: =W43-0.125 -> 7.25 | X44: =100-VLOOKUP(W44,'[1]Pricing '!$A$647:$K$671,11,FALSE) -> -3.0712603 | Y44: =X44-$U$2 -> -2.9462603 | Z44: =Z43-0.125 -> 7.625 | AA44: =100-VLOOKUP(Z44,'[1]Pricing '!$A$167:$K$191,11,FALSE) -> -2.7738846 | AB44: =AA44-$U$2 -> -2.6488846 | AC44: =AC43-0.125 -> 7.75 | AD44: =100-VLOOKUP(AC44,'[1]Pricing '!$A$674:$K$698,11,FALSE) -> -2.3317092 | AE44: =AD44-$U$2 -> -2.2067092 | AF44: =AF43-0.125 -> 7.375 | AG44: =100-VLOOKUP(AF44,'[1]Pricing '!$A$194:$K$218,11,FALSE) -> -2.7878836 | AH44: =AG44-$U$2 -> -2.6628836 | AI44: =AI43-0.125 -> 7.375 | AJ44: =100-VLOOKUP(AI44,'[1]Pricing '!$A$701:$K$725,11,FALSE) -> -2.7878836 | AK44: =AJ44-$U$2 -> -2.6628836
B45: {=INDEX($A$162:$DE$162,0,MATCH(B44,$A$162:$DE$162,0)-1)} -> 7.375 | C45: =100-VLOOKUP(B45,'[1]Pricing '!$A$6:$K$30,11,FALSE) -> -3.7977794 | D45: =C45-$U$2 -> -3.6727794 | E45: {=INDEX($A$162:$DE$162,0,MATCH(E44,$A$162:$DE$162,0)-1)} -> 7.625 | F45: =100-VLOOKUP(E45,'[1]Pricing '!$A$566:$K$590,11,FALSE) -> -4.2757203 | G45: =F45-$U$2 -> -4.1507203 | H45: =H44-0.125 -> 7.25 | I45: =100-VLOOKUP(H45,'[1]Pricing '!$A$59:$K$83,11,FALSE) -> -2.7422232 | J45: =I45-$U$2 -> -2.6172232 | K45: =K44-0.125 -> 7.25 | L45: =100-VLOOKUP(K45,'[1]Pricing '!$A$593:$K$617,11,FALSE) -> -2.7422232 | M45: =L45-$U$2 -> -2.6172232 | N45: =N44-0.125 -> 6.75 | O45: =100-VLOOKUP(N45,'[1]Pricing '!$A$86:$K$110,11,FALSE) -> -2.7662591 | P45: =O45-$U$2 -> -2.6412591 | Q45: =Q44-0.125 -> 6.75 | R45: =100-VLOOKUP(Q45,'[1]Pricing '!$A$620:$K$644,11,FALSE) -> -2.7662591 | S45: =R45-$U$2 -> -2.6412591 | T45: =T44-0.125 -> 6.875 | U45: =100-VLOOKUP(T45,'[1]Pricing '!$A$113:$K$137,11,FALSE) -> -2.9713409 | V45: =U45-$U$2 -> -2.8463409 | W45: =W44-0.125 -> 7.125 | X45: =100-VLOOKUP(W45,'[1]Pricing '!$A$647:$K$671,11,FALSE) -> -2.8466219 | Y45: =X45-$U$2 -> -2.7216219 | Z45: =Z44-0.125 -> 7.5 | AA45: =100-VLOOKUP(Z45,'[1]Pricing '!$A$167:$K$191,11,FALSE) -> -2.6012904 | AB45: =AA45-$U$2 -> -2.4762904 | AC45: =AC44-0.125 -> 7.625 | AD45: =100-VLOOKUP(AC45,'[1]Pricing '!$A$674:$K$698,11,FALSE) -> -2.7738846 | AE45: =AD45-$U$2 -> -2.6488846 | AF45: =AF44-0.125 -> 7.25 | AG45: =100-VLOOKUP(AF45,'[1]Pricing '!$A$194:$K$218,11,FALSE) -> -2.5922655 | AH45: =AG45-$U$2 -> -2.4672655 | AI45: =AI44-0.125 -> 7.25 | AJ45: =100-VLOOKUP(AI45,'[1]Pricing '!$A$701:$K$725,11,FALSE) -> -2.5922655 | AK45: =AJ45-$U$2 -> -2.4672655
B46: {=INDEX($A$162:$DE$162,0,MATCH(B45,$A$162:$DE$162,0)-1)} -> 7.25 | C46: =100-VLOOKUP(B46,'[1]Pricing '!$A$6:$K$30,11,FALSE) -> -3.3192232 | D46: =C46-$U$2 -> -3.1942232 | E46: {=INDEX($A$162:$DE$162,0,MATCH(E45,$A$162:$DE$162,0)-1)} -> 7.5 | F46: =100-VLOOKUP(E46,'[1]Pricing '!$A$566:$K$590,11,FALSE) -> -4.067206 | G46: =F46-$U$2 -> -3.942206 | H46: =H45-0.125 -> 7.125 | I46: =100-VLOOKUP(H46,'[1]Pricing '!$A$59:$K$83,11,FALSE) -> -2.2406343 | J46: =I46-$U$2 -> -2.1156343 | K46: =K45-0.125 -> 7.125 | L46: =100-VLOOKUP(K46,'[1]Pricing '!$A$593:$K$617,11,FALSE) -> -2.2406343 | M46: =L46-$U$2 -> -2.1156343 | N46: =N45-0.125 -> 6.625 | O46: =100-VLOOKUP(N46,'[1]Pricing '!$A$86:$K$110,11,FALSE) -> -2.5121048 | P46: =O46-$U$2 -> -2.3871048 | Q46: =Q45-0.125 -> 6.625 | R46: =100-VLOOKUP(Q46,'[1]Pricing '!$A$620:$K$644,11,FALSE) -> -2.5121048 | S46: =R46-$U$2 -> -2.3871048 | T46: =T45-0.125 -> 6.75 | U46: =100-VLOOKUP(T46,'[1]Pricing '!$A$113:$K$137,11,FALSE) -> -2.7272591 | V46: =U46-$U$2 -> -2.6022591 | W46: =W45-0.125 -> 7 | X46: =100-VLOOKUP(W46,'[1]Pricing '!$A$647:$K$671,11,FALSE) -> -3.1890398 | Y46: =X46-$U$2 -> -3.0640398 | Z46: =Z45-0.125 -> 7.375 | AA46: =100-VLOOKUP(Z46,'[1]Pricing '!$A$167:$K$191,11,FALSE) -> -2.2437664 | AB46: =AA46-$U$2 -> -2.1187664 | AC46: =AC45-0.125 -> 7.5 | AD46: =100-VLOOKUP(AC46,'[1]Pricing '!$A$674:$K$698,11,FALSE) -> -2.6012904 | AE46: =AD46-$U$2 -> -2.4762904 | AF46: =AF45-0.125 -> 7.125 | AG46: =100-VLOOKUP(AF46,'[1]Pricing '!$A$194:$K$218,11,FALSE) -> -2.8928149 | AH46: =AG46-$U$2 -> -2.7678149 | AI46: =AI45-0.125 -> 7.125 | AJ46: =100-VLOOKUP(AI46,'[1]Pricing '!$A$701:$K$725,11,FALSE) -> -2.8928149 | AK46: =AJ46-$U$2 -> -2.7678149
B47: {=INDEX($A$162:$DE$162,0,MATCH(B46,$A$162:$DE$162,0)-1)} -> 7.125 | C47: =100-VLOOKUP(B47,'[1]Pricing '!$A$6:$K$30,11,FALSE) -> -3.1056343 | D47: =C47-$U$2 -> -2.9806343 | E47: {=INDEX($A$162:$DE$162,0,MATCH(E46,$A$162:$DE$162,0)-1)} -> 7.375 | F47: =100-VLOOKUP(E47,'[1]Pricing '!$A$566:$K$590,11,FALSE) -> -3.7977794 | G47: =F47-$U$2 -> -3.6727794 | H47: =H46-0.125 -> 7 | I47: =100-VLOOKUP(H47,'[1]Pricing '!$A$59:$K$83,11,FALSE) -> -1.9244188 | J47: =I47-$U$2 -> -1.7994188 | K47: =K46-0.125 -> 7 | L47: =100-VLOOKUP(K47,'[1]Pricing '!$A$593:$K$617,11,FALSE) -> -1.9244188 | M47: =L47-$U$2 -> -1.7994188 | N47: =N46-0.125 -> 6.5 | O47: =100-VLOOKUP(N47,'[1]Pricing '!$A$86:$K$110,11,FALSE) -> -2.3369705 | P47: =O47-$U$2 -> -2.2119705 | Q47: =Q46-0.125 -> 6.5 | R47: =100-VLOOKUP(Q47,'[1]Pricing '!$A$620:$K$644,11,FALSE) -> -2.3369705 | S47: =R47-$U$2 -> -2.2119705 | T47: =T46-0.125 -> 6.625 | U47: =100-VLOOKUP(T47,'[1]Pricing '!$A$113:$K$137,11,FALSE) -> -2.5101048 | V47: =U47-$U$2 -> -2.3851048 | W47: =W46-0.125 -> 6.875 | X47: =100-VLOOKUP(W47,'[1]Pricing '!$A$647:$K$671,11,FALSE) -> -2.9713409 | Y47: =X47-$U$2 -> -2.8463409 | Z47: =Z46-0.125 -> 7.25 | AA47: =100-VLOOKUP(Z47,'[1]Pricing '!$A$167:$K$191,11,FALSE) -> -1.7710252 | AB47: =AA47-$U$2 -> -1.6460252 | AC47: =AC46-0.125 -> 7.375 | AD47: =100-VLOOKUP(AC47,'[1]Pricing '!$A$674:$K$698,11,FALSE) -> -2.2437664 | AE47: =AD47-$U$2 -> -2.1187664 | AF47: =AF46-0.125 -> 7 | AG47: =100-VLOOKUP(AF47,'[1]Pricing '!$A$194:$K$218,11,FALSE) -> -2.6913756 | AH47: =AG47-$U$2 -> -2.5663756 | AI47: =AI46-0.125 -> 7 | AJ47: =100-VLOOKUP(AI47,'[1]Pricing '!$A$701:$K$725,11,FALSE) -> -2.6913756 | AK47: =AJ47-$U$2 -> -2.5663756
B48: {=INDEX($A$162:$DE$162,0,MATCH(B47,$A$162:$DE$162,0)-1)} -> 7 | C48: =100-VLOOKUP(B48,'[1]Pricing '!$A$6:$K$30,11,FALSE) -> -2.7784188 | D48: =C48-$U$2 -> -2.6534188 | E48: {=INDEX($A$162:$DE$162,0,MATCH(E47,$A$162:$DE$162,0)-1)} -> 7.25 | F48: =100-VLOOKUP(E48,'[1]Pricing '!$A$566:$K$590,11,FALSE) -> -3.3192232 | G48: =F48-$U$2 -> -3.1942232 | H48: =H47-0.125 -> 6.875 | I48: =100-VLOOKUP(H48,'[1]Pricing '!$A$59:$K$83,11,FALSE) -> -1.6686371 | J48: =I48-$U$2 -> -1.5436371 | K48: =K47-0.125 -> 6.875 | L48: =100-VLOOKUP(K48,'[1]Pricing '!$A$593:$K$617,11,FALSE) -> -1.6686371 | M48: =L48-$U$2 -> -1.5436371 | N48: =N47-0.125 -> 6.375 | O48: =100-VLOOKUP(N48,'[1]Pricing '!$A$86:$K$110,11,FALSE) -> -2.0965438 | P48: =O48-$U$2 -> -1.9715438 | Q48: =Q47-0.125 -> 6.375 | R48: =100-VLOOKUP(Q48,'[1]Pricing '!$A$620:$K$644,11,FALSE) -> -2.0965438 | S48: =R48-$U$2 -> -1.9715438 | T48: =T47-0.125 -> 6.5 | U48: =100-VLOOKUP(T48,'[1]Pricing '!$A$113:$K$137,11,FALSE) -> -2.2889705 | V48: =U48-$U$2 -> -2.1639705 | W48: =W47-0.125 -> 6.75 | X48: =100-VLOOKUP(W48,'[1]Pricing '!$A$647:$K$671,11,FALSE) -> -2.7272591 | Y48: =X48-$U$2 -> -2.6022591 | Z48: =Z47-0.125 -> 7.125 | AA48: =100-VLOOKUP(Z48,'[1]Pricing '!$A$167:$K$191,11,FALSE) -> -2.015445 | AB48: =AA48-$U$2 -> -1.890445 | AC48: =AC47-0.125 -> 7.25 | AD48: =100-VLOOKUP(AC48,'[1]Pricing '!$A$674:$K$698,11,FALSE) -> -1.7710252 | AE48: =AD48-$U$2 -> -1.6460252 | AF48: =AF47-0.125 -> 6.875 | AG48: =100-VLOOKUP(AF48,'[1]Pricing '!$A$194:$K$218,11,FALSE) -> -2.1056408 | AH48: =AG48-$U$2 -> -1.9806408 | AI48: =AI47-0.125 -> 6.875 | AJ48: =100-VLOOKUP(AI48,'[1]Pricing '!$A$701:$K$725,11,FALSE) -> -2.1056408 | AK48: =AJ48-$U$2 -> -1.9806408
B49: {=INDEX($A$162:$DE$162,0,MATCH(B48,$A$162:$DE$162,0)-1)} -> 6.875 | C49: =100-VLOOKUP(B49,'[1]Pricing '!$A$6:$K$30,11,FALSE) -> -2.3166371 | D49: =C49-$U$2 -> -2.1916371 | E49: {=INDEX($A$162:$DE$162,0,MATCH(E48,$A$162:$DE$162,0)-1)} -> 7.125 | F49: =100-VLOOKUP(E49,'[1]Pricing '!$A$566:$K$590,11,FALSE) -> -3.1056343 | G49: =F49-$U$2 -> -2.9806343 | H49: =H48-0.125 -> 6.75 | I49: =100-VLOOKUP(H49,'[1]Pricing '!$A$59:$K$83,11,FALSE) -> -1.3690354 | J49: =I49-$U$2 -> -1.2440354 | K49: =K48-0.125 -> 6.75 | L49: =100-VLOOKUP(K49,'[1]Pricing '!$A$593:$K$617,11,FALSE) -> -1.3690354 | M49: =L49-$U$2 -> -1.2440354 | N49: =N48-0.125 -> 6.25 | O49: =100-VLOOKUP(N49,'[1]Pricing '!$A$86:$K$110,11,FALSE) -> -1.8050742 | P49: =O49-$U$2 -> -1.6800742 | Q49: =Q48-0.125 -> 6.25 | R49: =100-VLOOKUP(Q49,'[1]Pricing '!$A$620:$K$644,11,FALSE) -> -1.8050742 | S49: =R49-$U$2 -> -1.6800742 | T49: =T48-0.125 -> 6.375 | U49: =100-VLOOKUP(T49,'[1]Pricing '!$A$113:$K$137,11,FALSE) -> -2.0515438 | V49: =U49-$U$2 -> -1.9265438 | W49: =W48-0.125 -> 6.625 | X49: =100-VLOOKUP(W49,'[1]Pricing '!$A$647:$K$671,11,FALSE) -> -2.5101048 | Y49: =X49-$U$2 -> -2.3851048 | Z49: =Z48-0.125 -> 7 | AA49: =100-VLOOKUP(Z49,'[1]Pricing '!$A$167:$K$191,11,FALSE) -> -1.7028289 | AB49: =AA49-$U$2 -> -1.5778289 | AC49: =AC48-0.125 -> 7.125 | AD49: =100-VLOOKUP(AC49,'[1]Pricing '!$A$674:$K$698,11,FALSE) -> -2.015445 | AE49: =AD49-$U$2 -> -1.890445 | AF49: =AF48-0.125 -> 6.75 | AG49: =100-VLOOKUP(AF49,'[1]Pricing '!$A$194:$K$218,11,FALSE) -> -1.7302069 | AH49: =AG49-$U$2 -> -1.6052069 | AI49: =AI48-0.125 -> 6.75 | AJ49: =100-VLOOKUP(AI49,'[1]Pricing '!$A$701:$K$725,11,FALSE) -> -1.7302069 | AK49: =AJ49-$U$2 -> -1.6052069
B50: {=INDEX($A$162:$DE$162,0,MATCH(B49,$A$162:$DE$162,0)-1)} -> 6.75 | C50: =100-VLOOKUP(B50,'[1]Pricing '!$A$6:$K$30,11,FALSE) -> -1.7760354 | D50: =C50-$U$2 -> -1.6510354 | E50: {=INDEX($A$162:$DE$162,0,MATCH(E49,$A$162:$DE$162,0)-1)} -> 7 | F50: =100-VLOOKUP(E50,'[1]Pricing '!$A$566:$K$590,11,FALSE) -> -2.7784188 | G50: =F50-$U$2 -> -2.6534188 | H50: =H49-0.125 -> 6.625 | I50: =100-VLOOKUP(H50,'[1]Pricing '!$A$59:$K$83,11,FALSE) -> -1.3031419 | J50: =I50-$U$2 -> -1.1781419 | K50: =K49-0.125 -> 6.625 | L50: =100-VLOOKUP(K50,'[1]Pricing '!$A$593:$K$617,11,FALSE) -> -1.3031419 | M50: =L50-$U$2 -> -1.1781419 | N50: =N49-0.125 -> 6.125 | O50: =100-VLOOKUP(N50,'[1]Pricing '!$A$86:$K$110,11,FALSE) -> -1.4699316 | P50: =O50-$U$2 -> -1.3449316 | Q50: =Q49-0.125 -> 6.125 | R50: =100-VLOOKUP(Q50,'[1]Pricing '!$A$620:$K$644,11,FALSE) -> -1.4699316 | S50: =R50-$U$2 -> -1.3449316 | T50: =T49-0.125 -> 6.25 | U50: =100-VLOOKUP(T50,'[1]Pricing '!$A$113:$K$137,11,FALSE) -> -1.7630742 | V50: =U50-$U$2 -> -1.6380742 | W50: =W49-0.125 -> 6.5 | X50: =100-VLOOKUP(W50,'[1]Pricing '!$A$647:$K$671,11,FALSE) -> -2.2889705 | Y50: =X50-$U$2 -> -2.1639705 | Z50: =Z49-0.125 -> 6.875 | AA50: =100-VLOOKUP(Z50,'[1]Pricing '!$A$167:$K$191,11,FALSE) -> -1.5037035 | AB50: =AA50-$U$2 -> -1.3787035 | AC50: =AC49-0.125 -> 7 | AD50: =100-VLOOKUP(AC50,'[1]Pricing '!$A$674:$K$698,11,FALSE) -> -1.7028289 | AE50: =AD50-$U$2 -> -1.5778289 | AF50: =AF49-0.125 -> 6.625 | AG50: =100-VLOOKUP(AF50,'[1]Pricing '!$A$194:$K$218,11,FALSE) -> -1.6011124 | AH50: =AG50-$U$2 -> -1.4761124 | AI50: =AI49-0.125 -> 6.625 | AJ50: =100-VLOOKUP(AI50,'[1]Pricing '!$A$701:$K$725,11,FALSE) -> -1.6011124 | AK50: =AJ50-$U$2 -> -1.4761124
B51: {=INDEX($A$162:$DE$162,0,MATCH(B50,$A$162:$DE$162,0)-1)} -> 6.625 | C51: =100-VLOOKUP(B51,'[1]Pricing '!$A$6:$K$30,11,FALSE) -> -1.6001419 | D51: =C51-$U$2 -> -1.4751419 | E51: {=INDEX($A$162:$DE$162,0,MATCH(E50,$A$162:$DE$162,0)-1)} -> 6.875 | F51: =100-VLOOKUP(E51,'[1]Pricing '!$A$566:$K$590,11,FALSE) -> -2.3166371 | G51: =F51-$U$2 -> -2.1916371 | H51: =H50-0.125 -> 6.5 | I51: =100-VLOOKUP(H51,'[1]Pricing '!$A$59:$K$83,11,FALSE) -> -0.97955797 | J51: =I51-$U$2 -> -0.85455797 | K51: =K50-0.125 -> 6.5 | L51: =100-VLOOKUP(K51,'[1]Pricing '!$A$593:$K$617,11,FALSE) -> -0.97955797 | M51: =L51-$U$2 -> -0.85455797 | N51: =N50-0.125 -> 6 | O51: =100-VLOOKUP(N51,'[1]Pricing '!$A$86:$K$110,11,FALSE) -> -1.2045454 | P51: =O51-$U$2 -> -1.0795454 | Q51: =Q50-0.125 -> 6 | R51: =100-VLOOKUP(Q51,'[1]Pricing '!$A$620:$K$644,11,FALSE) -> -1.2045454 | S51: =R51-$U$2 -> -1.0795454 | T51: =T50-0.125 -> 6.125 | U51: =100-VLOOKUP(T51,'[1]Pricing '!$A$113:$K$137,11,FALSE) -> -1.4469316 | V51: =U51-$U$2 -> -1.3219316 | W51: =W50-0.125 -> 6.375 | X51: =100-VLOOKUP(W51,'[1]Pricing '!$A$647:$K$671,11,FALSE) -> -2.0515438 | Y51: =X51-$U$2 -> -1.9265438 | Z51: =Z50-0.125 -> 6.75 | AA51: =100-VLOOKUP(Z51,'[1]Pricing '!$A$167:$K$191,11,FALSE) -> -0.95061475 | AB51: =AA51-$U$2 -> -0.82561475 | AC51: =AC50-0.125 -> 6.875 | AD51: =100-VLOOKUP(AC51,'[1]Pricing '!$A$674:$K$698,11,FALSE) -> -1.5037035 | AE51: =AD51-$U$2 -> -1.3787035 | AF51: =AF50-0.125 -> 6.5 | AG51: =100-VLOOKUP(AF51,'[1]Pricing '!$A$194:$K$218,11,FALSE) -> -1.3821443 | AH51: =AG51-$U$2 -> -1.2571443 | AI51: =AI50-0.125 -> 6.5 | AJ51: =100-VLOOKUP(AI51,'[1]Pricing '!$A$701:$K$725,11,FALSE) -> -1.3821443 | AK51: =AJ51-$U$2 -> -1.2571443
B52: {=INDEX($A$162:$DE$162,0,MATCH(B51,$A$162:$DE$162,0)-1)} -> 6.5 | C52: =100-VLOOKUP(B52,'[1]Pricing '!$A$6:$K$30,11,FALSE) -> -1.228558 | D52: =C52-$U$2 -> -1.103558 | E52: {=INDEX($A$162:$DE$162,0,MATCH(E51,$A$162:$DE$162,0)-1)} -> 6.75 | F52: =100-VLOOKUP(E52,'[1]Pricing '!$A$566:$K$590,11,FALSE) -> -1.7760354 | G52: =F52-$U$2 -> -1.6510354 | H52: =H51-0.125 -> 6.375 | I52: =100-VLOOKUP(H52,'[1]Pricing '!$A$59:$K$83,11,FALSE) -> -0.61457311 | J52: =I52-$U$2 -> -0.48957311 | K52: =K51-0.125 -> 6.375 | L52: =100-VLOOKUP(K52,'[1]Pricing '!$A$593:$K$617,11,FALSE) -> -0.61457311 | M52: =L52-$U$2 -> -0.48957311 | N52: =N51-0.125 -> 5.875 | O52: =100-VLOOKUP(N52,'[1]Pricing '!$A$86:$K$110,11,FALSE) -> -0.93241865 | P52: =O52-$U$2 -> -0.80741865 | Q52: =Q51-0.125 -> 5.875 | R52: =100-VLOOKUP(Q52,'[1]Pricing '!$A$620:$K$644,11,FALSE) -> -0.93241865 | S52: =R52-$U$2 -> -0.80741865 | T52: =T51-0.125 -> 6 | U52: =100-VLOOKUP(T52,'[1]Pricing '!$A$113:$K$137,11,FALSE) -> -1.1825454 | V52: =U52-$U$2 -> -1.0575454 | W52: =W51-0.125 -> 6.25 | X52: =100-VLOOKUP(W52,'[1]Pricing '!$A$647:$K$671,11,FALSE) -> -1.7630742 | Y52: =X52-$U$2 -> -1.6380742 | Z52: =Z51-0.125 -> 6.625 | AA52: =100-VLOOKUP(Z52,'[1]Pricing '!$A$167:$K$191,11,FALSE) -> -0.96325543 | AB52: =AA52-$U$2 -> -0.83825543 | AC52: =AC51-0.125 -> 6.75 | AD52: =100-VLOOKUP(AC52,'[1]Pricing '!$A$674:$K$698,11,FALSE) -> -0.95061475 | AE52: =AD52-$U$2 -> -0.82561475 | AF52: =AF51-0.125 -> 6.375 | AG52: =100-VLOOKUP(AF52,'[1]Pricing '!$A$194:$K$218,11,FALSE) -> -1.1276478 | AH52: =AG52-$U$2 -> -1.0026478 | AI52: =AI51-0.125 -> 6.375 | AJ52: =100-VLOOKUP(AI52,'[1]Pricing '!$A$701:$K$725,11,FALSE) -> -1.1276478 | AK52: =AJ52-$U$2 -> -1.0026478
B53: {=INDEX($A$162:$DE$162,0,MATCH(B52,$A$162:$DE$162,0)-1)} -> 6.375 | C53: =100-VLOOKUP(B53,'[1]Pricing '!$A$6:$K$30,11,FALSE) -> -0.89657311 | D53: =C53-$U$2 -> -0.77157311 | E53: {=INDEX($A$162:$DE$162,0,MATCH(E52,$A$162:$DE$162,0)-1)} -> 6.625 | F53: =100-VLOOKUP(E53,'[1]Pricing '!$A$566:$K$590,11,FALSE) -> -1.6001419 | G53: =F53-$U$2 -> -1.4751419 | H53: =H52-0.125 -> 6.25 | I53: =100-VLOOKUP(H53,'[1]Pricing '!$A$59:$K$83,11,FALSE) -> -0.21893415 | J53: =I53-$U$2 -> -0.093934154 | K53: =K52-0.125 -> 6.25 | L53: =100-VLOOKUP(K53,'[1]Pricing '!$A$593:$K$617,11,FALSE) -> -0.21893415 | M53: =L53-$U$2 -> -0.093934154 | N53: =N52-0.125 -> 5.75 | O53: =100-VLOOKUP(N53,'[1]Pricing '!$A$86:$K$110,11,FALSE) -> -0.5290574 | P53: =O53-$U$2 -> -0.4040574 | Q53: =Q52-0.125 -> 5.75 | R53: =100-VLOOKUP(Q53,'[1]Pricing '!$A$620:$K$644,11,FALSE) -> -0.5290574 | S53: =R53-$U$2 -> -0.4040574 | T53: =T52-0.125 -> 5.875 | U53: =100-VLOOKUP(T53,'[1]Pricing '!$A$113:$K$137,11,FALSE) -> -0.91441865 | V53: =U53-$U$2 -> -0.78941865 | W53: =W52-0.125 -> 6.125 | X53: =100-VLOOKUP(W53,'[1]Pricing '!$A$647:$K$671,11,FALSE) -> -1.4469316 | Y53: =X53-$U$2 -> -1.3219316 | Z53: =Z52-0.125 -> 6.5 | AA53: =100-VLOOKUP(Z53,'[1]Pricing '!$A$167:$K$191,11,FALSE) -> -0.69611537 | AB53: =AA53-$U$2 -> -0.57111537 | AC53: =AC52-0.125 -> 6.625 | AD53: =100-VLOOKUP(AC53,'[1]Pricing '!$A$674:$K$698,11,FALSE) -> -0.96325543 | AE53: =AD53-$U$2 -> -0.83825543 | AF53: =AF52-0.125 -> 6.25 | AG53: =100-VLOOKUP(AF53,'[1]Pricing '!$A$194:$K$218,11,FALSE) -> -0.75800343 | AH53: =AG53-$U$2 -> -0.63300343 | AI53: =AI52-0.125 -> 6.25 | AJ53: =100-VLOOKUP(AI53,'[1]Pricing '!$A$701:$K$725,11,FALSE) -> -0.75800343 | AK53: =AJ53-$U$2 -> -0.63300343
...

Sheet FT_LLPAS
T1: 2 of 12
B2: AmWest Corporate Office
B3: 6 Pointe Dr. Suite 300
B4: Brea, CA 92821
B5: (714) 831-3333
B6: www.amwestwholesale.com
E7: Wholesale Rate sheet - Consumer Paid | J7: Effective: | L7: =CONV!R7 -> 46101 | O7: =CONV!W7 -> 0
B8: LOAN LOCK INFO
B9: Lock Desk : Email: Lockdesk@amwestfunding.com | H9: Phone: (714) 831-3299 | L9: eFax: (714) 905-5620 | Q9: Lock Hours: 8:30AM-5:00 PM PST
B10: ANNOUNCEMENT
B15: FAST TRACK LLPA's (FFT & FMFT)
B17: Purchase(Loan terms > 15 years) | N17: >4 Owned properties including Financed LLPA
B18: FICO/LTV | C18: ≤30 | D18: 30.01-60 | E18: 60.01-70 | F18: 70.01-75 | G18: 75.01-80 | H18: 80.01-85 | I18: 85.01-90 | J18: 90.01-95 | K18: >95 | N18: 15 MAX owned properties on CONVENTIONAL
B19: ≥800 | C19: 0 | D19: 0 | E19: 0 | F19: 0 | G19: 0.375 | H19: 0.75 | I19: 0.75 | J19: 0.875 | K19: 0.875 | N19: 5-7 properties | T19: 0
B20: 780-799 | C20: 0 | D20: 0 | E20: 0 | F20: 0 | G20: 0.375 | H20: 0.75 | I20: 0.75 | J20: 0.875 | K20: 0.875 | N20: 8-10 properties | T20: 0.25
B21: 760-779 | C21: 0 | D21: 0 | E21: 0 | F21: 0.25 | G21: 0.625 | H21: 1 | I21: 1 | J21: 1.125 | K21: 1 | N21: 11-15 properties | T21: 0.5
B22: 740-759 | C22: 0 | D22: 0 | E22: 0.125 | F22: 0.375 | G22: 0.875 | H22: 1.375 | I22: 1.25 | J22: 1.25 | K22: 1.25
B23: 720-739 | C23: 0 | D23: 0 | E23: 0.25 | F23: 0.75 | G23: 1.25 | H23: 1.625 | I23: 1.5 | J23: 1.5 | K23: 1.5
B24: 700-719 | C24: 0 | D24: 0 | E24: 0.375 | F24: 0.875 | G24: 1.375 | H24: 1.875 | I24: 1.75 | J24: 1.75 | K24: 1.625
B25: 680-699 | C25: 0 | D25: 0 | E25: 0.625 | F25: 1.125 | G25: 1.75 | H25: 2.25 | I25: 2 | J25: 2 | K25: 1.875
B26: 660-679 | C26: 0.375 | D26: 0.375 | E26: 1.125 | F26: 1.75 | G26: 2.25 | H26: 2.5 | I26: 2.25 | J26: 2.25 | K26: 2
B27: 640-659 | C27: 0.5 | D27: 0.5 | E27: 1.625 | F27: 2 | G27: 2.75 | H27: 3 | I27: 2.5 | J27: 2.5 | K27: 2.25
B28: 620-639 | C28: 0.625 | D28: 0.75 | E28: 2.125 | F28: 2.75 | G28: 3.375 | H28: 3.5 | I28: 3.25 | J28: 2.875 | K28: 2.5
B29: Purchase Loan Additional (all amortization terms) | N29: OTHER PRICE ADJUSTMENTS
B30: LTV | C30: ≤30 | D30: 30.01-60 | E30: 60.01-70 | F30: 70.01-75 | G30: 75.01-80 | H30: 80.01-85 | I30: 85.01-90 | J30: 90.01-95 | K30: >95 | N30: Loan Amt $50,000- $74,999 | T30: 1.5
B31: ARMs | C31: 0 | D31: 0 | E31: 0 | F31: 0 | G31: 0 | H31: 0 | I31: 0 | J31: 0.25 | K31: N/A | N31: Loan Amt $75,000 to $99,999 | T31: 0.75
B32: Attached Condo | C32: 0 | D32: 0 | E32: 0.125 | F32: 0.125 | G32: 0.75 | H32: 0.75 | I32: 0.75 | J32: 0.75 | K32: 0.75 | N32: Loan Amt $100,000 to $149,999 | T32: 0.125
B33: Sub Financing | C33: 0.625 | D33: 0.625 | E33: 0.625 | F33: 0.875 | G33: 1.125 | H33: 1.125 | I33: 1.125 | J33: 1.875 | K33: 1.875 | N33: Texas 50 A (6) | T33: 0.125
B34: HighBal Fixed | C34: 0.5 | D34: 0.5 | E34: 0.75 | F34: 0.75 | G34: 1 | H34: 1 | I34: 1 | J34: 1 | K34: 1 | N34: 60 DAYS LOCK (based on 30 days price) | T34: 0.25
B35: HighBal ARM | C35: 1.25 | D35: 1.25 | E35: 1.5 | F35: 1.5 | G35: 2.5 | H35: 2.5 | I35: 2.5 | J35: 2.75 | K35: N/A
B36: Baltimore County-MD | C36: 0.25 | D36: 0.25 | E36: 0.25 | F36: 0.375 | G36: 0.375 | H36: 0.5 | I36: 0.5 | J36: 0.5 | K36: 0.5
B37: Rate&Term (Loan terms > 15 years)
B38: FICO/LTV | C38: ≤30 | D38: 30.01-60 | E38: 60.01-70 | F38: 70.01-75 | G38: 75.01-80 | H38: 80.01-85 | I38: 85.01-90 | J38: 90.01-95 | K38: >95
B39: ≥800 | C39: 0 | D39: 0 | E39: 0 | F39: 0.125 | G39: 0.5 | H39: 1 | I39: 1 | J39: 1 | K39: 1.125 | N39: State Adjuster (FIXED Program) | S39: 30/20Y | T39: 15/10Y
B40: 780-799 | C40: 0 | D40: 0 | E40: 0 | F40: 0.125 | G40: 0.5 | H40: 1 | I40: 1 | J40: 1 | K40: 1.125 | N40: Group 1 | O40: TX | S40: -0.125 | T40: -0.125
B41: 760-779 | C41: 0 | D41: 0 | E41: 0.125 | F41: 0.375 | G41: 0.875 | H41: 1.375 | I41: 1.25 | J41: 1.25 | K41: 1.375
B42: 740-759 | C42: 0 | D42: 0 | E42: 0.25 | F42: 0.75 | G42: 1.125 | H42: 1.75 | I42: 1.625 | J42: 1.625 | K42: 1.75
B43: 720-739 | C43: 0 | D43: 0 | E43: 0.5 | F43: 1 | G43: 1.625 | H43: 2.125 | I43: 2 | J43: 1.875 | K43: 2
B44: 700-719 | C44: 0 | D44: 0 | E44: 0.625 | F44: 1.25 | G44: 1.875 | H44: 2.5 | I44: 2.25 | J44: 2.25 | K44: 2.375
B45: 680-699 | C45: 0 | D45: 0 | E45: 0.875 | F45: 1.625 | G45: 2.25 | H45: 2.875 | I45: 2.625 | J45: 2.375 | K45: 2.5
...

Sheet LLPAS
T1: 4 of 11
B2: AmWest Corporate Office | R2: Lock Expiration Dates
B3: 6 Pointe Dr. Suite 300
B4: Brea, CA 92821 | R4: 30 Day Lock | T4: =[2]FNMA!P4 -> 45980
B5: (714) 831-3333 | R5: 45 Day Lock | T5: =[2]FNMA!P5 -> 45995
B6: www.amwestwholesale.com | R6: 60 Day Lock | T6: =[2]FNMA!P6 -> 46010
F7: Wholesale Rate sheet - Consumer Paid | J7: Effective: | L7: =TODAY() -> 46101 | O7: =[2]FNMA!M7 -> 8:00 AM PST
B8: LOAN LOCK INFO
B9: Lock Desk : Email: Lockdesk@amwestfunding.com | H9: Phone: (714) 831-3299 | L9: eFax: (714) 905-5620 | Q9: Lock Hours: 8:30AM-5:00 PM PST
B10: ANNOUNCEMENT
B15: AGENCY LLPAs (DU/LP) - FIXED & ARM (Incl. HomeOne, RefiNow)
B17: Purchase(Loan terms > 15 years) | N17: NOO Additional Adjustments (30YR FIXED ONLY)
B18: FICO/LTV | C18: ≤30 | D18: 30.01-60 | E18: 60.01-70 | F18: 70.01-75 | G18: 75.01-80 | H18: 80.01-85 | I18: 85.01-90 | J18: 90.01-95 | K18: >95 | N18: LTV | O18: ≤30 | P18: 30.01-60 | Q18: 60.01-70 | R18: 70.01-75 | S18: 75.01-80 | T18: 80.01-85
B19: ≥800 | C19: 0 | D19: 0 | E19: 0 | F19: 0 | G19: 0.375 | H19: 0.75 | I19: 0.75 | J19: 0.875 | K19: 0.875 | N19: Purchase | O19: -0.375 | P19: -0.375 | Q19: -1 | R19: -1.125 | S19: -1.25 | T19: -0.75
B20: 780-799 | C20: 0 | D20: 0 | E20: 0 | F20: 0 | G20: 0.375 | H20: 0.75 | I20: 0.75 | J20: 0.875 | K20: 0.875 | N20: Rate&Term | O20: -0.875 | P20: -0.875 | Q20: -1.125 | R20: -1.25 | S20: -1.75 | T20: -0.625
B21: 760-779 | C21: 0 | D21: 0 | E21: 0 | F21: 0.25 | G21: 0.625 | H21: 1 | I21: 1 | J21: 1.125 | K21: 1 | N21: Cash Out | O21: -1.125 | P21: -1.125 | Q21: -1.25 | R21: -1.25 | S21: -0.25 | T21: -0.25
B22: 740-759 | C22: 0 | D22: 0 | E22: 0.125 | F22: 0.375 | G22: 0.875 | H22: 1.375 | I22: 1.25 | J22: 1.25 | K22: 1.25 | N22: High Balance | O22: 1.25 | P22: 1.25 | Q22: 1.25 | R22: 1.25 | S22: 1.25 | T22: 1.25
B23: 720-739 | C23: 0 | D23: 0 | E23: 0.25 | F23: 0.75 | G23: 1.25 | H23: 1.625 | I23: 1.5 | J23: 1.5 | K23: 1.5 | N23: Fico 680-719 | O23: 0.25 | P23: 0.25 | Q23: -0.25 | R23: 0.25 | S23: -0.25 | T23: 0.25
B24: 700-719 | C24: 0 | D24: 0 | E24: 0.375 | F24: 0.875 | G24: 1.375 | H24: 1.875 | I24: 1.75 | J24: 1.75 | K24: 1.625
B25: 680-699 | C25: 0 | D25: 0 | E25: 0.625 | F25: 1.125 | G25: 1.75 | H25: 2.25 | I25: 2 | J25: 2 | K25: 1.875 | N25: 2nd Home Additional Adjustments (30YR FIXED ONLY)
B26: 660-679 | C26: 0.375 | D26: 0.375 | E26: 1.125 | F26: 1.75 | G26: 2.25 | H26: 2.5 | I26: 2.25 | J26: 2.25 | K26: 2 | N26: LTV | O26: ≤30 | P26: 30.01-60 | Q26: 60.01-70 | R26: 70.01-75 | S26: 75.01-80 | T26: 80.01-85
B27: 640-659 | C27: 0.5 | D27: 0.5 | E27: 1.625 | F27: 2 | G27: 2.75 | H27: 3 | I27: 2.5 | J27: 2.5 | K27: 2.25 | N27: Purchase / R&T | O27: -0.375 | P27: -0.375 | Q27: -0.375 | R27: 0 | S27: 0 | T27: 0
B28: 620-639 | C28: 0.625 | D28: 0.75 | E28: 2.125 | F28: 2.75 | G28: 3.375 | H28: 3.5 | I28: 3.25 | J28: 2.875 | K28: 2.5 | N28: Cash Out | O28: -0.375 | P28: -0.375 | Q28: 0 | R28: 0 | S28: 0 | T28: 0
B29: Purchase Loan Additional (all amortization terms)
B30: LTV | C30: ≤30 | D30: 30.01-60 | E30: 60.01-70 | F30: 70.01-75 | G30: 75.01-80 | H30: 80.01-85 | I30: 85.01-90 | J30: 90.01-95 | K30: >95
B31: ARMs | C31: 0 | D31: 0 | E31: 0 | F31: 0 | G31: 0 | H31: 0 | I31: 0 | J31: 0.25 | K31: N/A
B32: Attached Condo | C32: 0 | D32: 0 | E32: 0.125 | F32: 0.125 | G32: 0.75 | H32: 0.75 | I32: 0.75 | J32: 0.75 | K32: 0.75
B33: 2-4 Units | C33: 0 | D33: 0 | E33: 0.375 | F33: 0.375 | G33: 0.625 | H33: 0.625 | I33: 0.875 | J33: 0.875 | K33: N/A | O33: >4 Owned properties including Financed LLPA
B34: N/O/O | C34: 1.125 | D34: 1.125 | E34: 1.625 | F34: 2.125 | G34: 3.375 | H34: 4.125 | I34: N/A | J34: N/A | K34: N/A | O34: 15 MAX owned properties on CONVENTIONAL
B35: Second Homes | C35: 1.125 | D35: 1.125 | E35: 1.625 | F35: 2.125 | G35: 3.375 | H35: 4.125 | I35: 4.125 | J35: N/A | K35: N/A | O35: 5-7 properties | S35: 0
B36: Sub Financing | C36: 0.625 | D36: 0.625 | E36: 0.625 | F36: 0.875 | G36: 1.125 | H36: 1.125 | I36: 1.125 | J36: 1.875 | K36: 1.875 | O36: 8-10 properties | S36: 0.25
B37: HighBal Fixed | C37: 0.5 | D37: 0.5 | E37: 0.75 | F37: 0.75 | G37: 1 | H37: 1 | I37: 1 | J37: 1 | K37: 1 | O37: 11-15 properties | S37: 0.5
B38: HighBal ARM | C38: 1.25 | D38: 1.25 | E38: 1.5 | F38: 1.5 | G38: 2.5 | H38: 2.5 | I38: 2.5 | J38: 2.75 | K38: N/A
B39: Baltimore County-MD | C39: 0.25 | D39: 0.25 | E39: 0.25 | F39: 0.375 | G39: 0.375 | H39: 0.5 | I39: 0.5 | J39: 0.5 | K39: 0.5
B40: Rate&Term (Loan terms > 15 years) | N40: OTHER PRICE ADJUSTMENTS
B41: FICO/LTV | C41: ≤30 | D41: 30.01-60 | E41: 60.01-70 | F41: 70.01-75 | G41: 75.01-80 | H41: 80.01-85 | I41: 85.01-90 | J41: 90.01-95 | K41: >95 | N41: Loan Amt $50,000- $74,999 | T41: 1.5
B42: ≥800 | C42: 0 | D42: 0 | E42: 0 | F42: 0.125 | G42: 0.5 | H42: 1 | I42: 1 | J42: 1 | K42: 1.125 | N42: Loan Amt $75,000 to $99,999 | T42: 0.75
B43: 780-799 | C43: 0 | D43: 0 | E43: 0 | F43: 0.125 | G43: 0.5 | H43: 1 | I43: 1 | J43: 1 | K43: 1.125 | N43: Loan Amt $100,000 to $149,999 | T43: 0.125
B44: 760-779 | C44: 0 | D44: 0 | E44: 0.125 | F44: 0.375 | G44: 0.875 | H44: 1.375 | I44: 1.25 | J44: 1.25 | K44: 1.375 | N44: Texas 50 A (6) | T44: 0.125
B45: 740-759 | C45: 0 | D45: 0 | E45: 0.25 | F45: 0.75 | G45: 1.125 | H45: 1.75 | I45: 1.625 | J45: 1.625 | K45: 1.75 | N45: 1 year tax return >90% LTV (self-employment) | T45: 0.25
...

Sheet HR & HP
P1: 4 of 12
B2: AmWest Corporate Office
B3: 6 Pointe Dr. Suite 300
B4: Brea, CA 92821
B5: (714) 831-3333
B6: www.amwestwholesale.com
F7: Wholesale Rate sheet - Consumer Paid | J7: Effective: | L7: =TODAY() -> 46101 | M7: =LLPAS!O7 -> 8:00 AM PST
B8: LOAN LOCK INFO
B9: Lock Desk : Email: Lockdesk@amwestfunding.com | G9: Phone: (714) 831-3299 | J9: eFax: (714) 905-5620 | M9: Lock Hours: 8:30AM-5:00 PM PST
B10: ANNOUNCEMENT
B12: HomeReady & HomePossible Enhancement programs with $2,500 credits available!!
B15: FANNIE MAE HOMEREADY CONFORMING & HIGH BALANCE- FIXED & ARM
B16: Conforming & High Balance FIXED | H16: CONFORMING ARMS | V16: LINKED
B17: (FCF30HR) 30 YR | E17: (FCF30HR HB) 30 YR | H17: (CA5/6 HR) 5YR ARM | K17: (CA7/6 HR) 7YR ARM | N17: (CA10/6 HR) 10YR ARM | V17: 45 DAY COST
B18: RATE | C18: 30 Days | D18: 45 Days | E18: RATE | F18: 30 Days | G18: 45 Days | H18: RATE | I18: 30 Days | J18: 45 Days | K18: RATE | L18: 30 Days | M18: 45 Days | N18: RATE | O18: 30 Days | P18: 45 Days | V18: -0.125
B19: 5.375 | C19: =100-VLOOKUP(B19,'[1]Pricing '!$A$140:$K$164,11,FALSE) -> 3.5787035 | D19: =C19-$V$18 -> 3.7037035 | E19: 5.375 | F19: =100-VLOOKUP(E19,'[1]Pricing '!$A$2034:$K$2059,11,FALSE) -> 3.6732835 | G19: =F19-$V$18 -> 3.7982835 | H19: 5.125 | I19: =100-VLOOKUP(H19,'[1]Pricing '!$A$353:$K$372,11,FALSE) -> 0.90085543 | J19: =I19-$V$18 -> 1.0258554 | K19: 5.125 | L19: =100-VLOOKUP(K19,'[1]Pricing '!$A$375:$K$394,11,FALSE) -> 1.2179367 | M19: =L19-$V$18 -> 1.3429367 | N19: 5.125 | O19: =100-VLOOKUP(N19,'[1]Pricing '!$A$397:$K$416,11,FALSE) -> 1.9186049 | P19: =O19-$V$18 -> 2.0436049
B20: =B19+0.125 -> 5.5 | C20: =100-VLOOKUP(B20,'[1]Pricing '!$A$140:$K$164,11,FALSE) -> 2.9310002 | D20: =C20-$V$18 -> 3.0560002 | E20: =E19+0.125 -> 5.5 | F20: =100-VLOOKUP(E20,'[1]Pricing '!$A$2034:$K$2059,11,FALSE) -> 3.0628427 | G20: =F20-$V$18 -> 3.1878427 | H20: =H19+0.125 -> 5.25 | I20: =100-VLOOKUP(H20,'[1]Pricing '!$A$353:$K$372,11,FALSE) -> 0.66179644 | J20: =I20-$V$18 -> 0.78679644 | K20: =K19+0.125 -> 5.25 | L20: =100-VLOOKUP(K20,'[1]Pricing '!$A$375:$K$394,11,FALSE) -> 0.93232517 | M20: =L20-$V$18 -> 1.0573252 | N20: =N19+0.125 -> 5.25 | O20: =100-VLOOKUP(N20,'[1]Pricing '!$A$397:$K$416,11,FALSE) -> 1.5031459 | P20: =O20-$V$18 -> 1.6281459
B21: =B20+0.125 -> 5.625 | C21: =100-VLOOKUP(B21,'[1]Pricing '!$A$140:$K$164,11,FALSE) -> 2.3090477 | D21: =C21-$V$18 -> 2.4340477 | E21: =E20+0.125 -> 5.625 | F21: =100-VLOOKUP(E21,'[1]Pricing '!$A$2034:$K$2059,11,FALSE) -> 2.4840853 | G21: =F21-$V$18 -> 2.6090853 | H21: =H20+0.125 -> 5.375 | I21: =100-VLOOKUP(H21,'[1]Pricing '!$A$353:$K$372,11,FALSE) -> 0.4461309 | J21: =I21-$V$18 -> 0.5711309 | K21: =K20+0.125 -> 5.375 | L21: =100-VLOOKUP(K21,'[1]Pricing '!$A$375:$K$394,11,FALSE) -> 0.65604786 | M21: =L21-$V$18 -> 0.78104786 | N21: =N20+0.125 -> 5.375 | O21: =100-VLOOKUP(N21,'[1]Pricing '!$A$397:$K$416,11,FALSE) -> 1.1581668 | P21: =O21-$V$18 -> 1.2831668
B22: =B21+0.125 -> 5.75 | C22: =100-VLOOKUP(B22,'[1]Pricing '!$A$140:$K$164,11,FALSE) -> 1.7066396 | D22: =C22-$V$18 -> 1.8316396 | E22: =E21+0.125 -> 5.75 | F22: =100-VLOOKUP(E22,'[1]Pricing '!$A$2034:$K$2059,11,FALSE) -> 1.9879593 | G22: =F22-$V$18 -> 2.1129593 | H22: =H21+0.125 -> 5.5 | I22: =100-VLOOKUP(H22,'[1]Pricing '!$A$353:$K$372,11,FALSE) -> 0.22122219 | J22: =I22-$V$18 -> 0.34622219 | K22: =K21+0.125 -> 5.5 | L22: =100-VLOOKUP(K22,'[1]Pricing '!$A$375:$K$394,11,FALSE) -> 0.4173028 | M22: =L22-$V$18 -> 0.5423028 | N22: =N21+0.125 -> 5.5 | O22: =100-VLOOKUP(N22,'[1]Pricing '!$A$397:$K$416,11,FALSE) -> 0.84129533 | P22: =O22-$V$18 -> 0.96629533
B23: =B22+0.125 -> 5.875 | C23: =100-VLOOKUP(B23,'[1]Pricing '!$A$140:$K$164,11,FALSE) -> 1.0933457 | D23: =C23-$V$18 -> 1.2183457 | E23: =E22+0.125 -> 5.875 | F23: =100-VLOOKUP(E23,'[1]Pricing '!$A$2034:$K$2059,11,FALSE) -> 1.4903091 | G23: =F23-$V$18 -> 1.6153091 | H23: =H22+0.125 -> 5.625 | I23: =100-VLOOKUP(H23,'[1]Pricing '!$A$353:$K$372,11,FALSE) -> -0.01757126 | J23: =I23-$V$18 -> 0.10742874 | K23: =K22+0.125 -> 5.625 | L23: =100-VLOOKUP(K23,'[1]Pricing '!$A$375:$K$394,11,FALSE) -> 0.23646566 | M23: =L23-$V$18 -> 0.36146566 | N23: =N22+0.125 -> 5.625 | O23: =100-VLOOKUP(N23,'[1]Pricing '!$A$397:$K$416,11,FALSE) -> 0.57159726 | P23: =O23-$V$18 -> 0.69659726
